Workbook

Sheet صفحة الرئيسية
C2: الذهاب الى | E2: المجموع الكلي 12 شهراً
C3: شهر 1
C4: شهر 2 | E4: ='1'!D6+'2'!D6+'3'!D6+'4'!D6+'5'!D6+'6'!D6+'7'!D6+'8'!D6+'9'!D6+'10'!D6+'11'!D6+'12'!D6 -> 0 | H4: المجموع الكلي للراتب 12 شهر | K4: النسبة المئوية للراتب الشهري فقط | P4: النسبة المئوية للراتب الشهري فقط
C5: شهر 3 | K5: الاستثمار | L5: ادخار الحج | M5: ادخار ( تأمين و تسجيل + ثياب العيد ) | N5: مصاريف متنوعة | P5: الاستثمار | R5: مصاريف متنوعة
C6: شهر 4 | E6: مجموع الدخل 12 شهر | K6: =E42/E4*1 -> #DIV/0! | L6: =E39/E4*1 -> #DIV/0! | M6: =E44/E4*1 -> #DIV/0! | N6: =(E95-K7)/E4*1 -> #DIV/0! | P6: =E42/E4*1 -> #DIV/0! | R6: =(E95-K7)/E4*1 -> #DIV/0!
C7: شهر 5 | E7: ='1'!D9+'2'!D9+'3'!D9+'4'!D9+'5'!D9+'6'!D9+'7'!D9+'8'!D9+'9'!D9+'10'!D9+'11'!D9+'12'!D9 -> 0 | H7: المجموع الكلي لغلاء المعيشة 12 شهر | K7: =E42 -> 0 | L7: =E39 -> 0 | M7: =E44 -> 0 | N7: =(E4*N6)/1 -> #DIV/0! | P7: =E42 -> 0 | R7: =(E4*N6)/1 -> #DIV/0!
C8: شهر 6 | E8: ='1'!D10+'2'!D10+'3'!D10+'4'!D10+'5'!D10+'6'!D10+'7'!D10+'8'!D10+'9'!D10+'10'!D10+'11'!D10+'12'!D10 -> 0 | H8: المجموع الكلي لعلاوة إسكان 12 شهر | K8: =(N6+L6+K6+M6) -> #DIV/0! | M8: مجموع النسبة المئوية الكلي | P8: =(R6+P6) -> #DIV/0! | R8: مجموع النسبة المئوية الكلي
C9: شهر 7 | E9: ='1'!D11+'2'!D11+'3'!D11+'4'!D11+'5'!D11+'6'!D11+'7'!D11+'8'!D11+'9'!D11+'10'!D11+'11'!D11+'12'!D11 -> 0 | H9: المجموع الكلي لدعم اللحوم | K9: =K7+L7+N7+M7 -> #DIV/0! | P9: =P7+R7 -> #DIV/0!
C10: شهر 8 | E10: ='1'!D12+'2'!D12+'3'!D12+'4'!D12+'5'!D12+'6'!D12+'7'!D12+'8'!D12+'9'!D12+'10'!D12+'11'!D12+'12'!D12 -> 0 | H10: المجموع الكلي لمساعدات خيرية 12 شهر | K10: =1-K8 -> #DIV/0! | M10: المتبقي من الراتب ١٢ شهر | P10: =1-P8 -> #DIV/0! | R10: المتبقي من الراتب ١٢ شهر
C11: شهر 9 | E11: ='1'!D13+'2'!D13+'3'!D13+'4'!D13+'5'!D13+'6'!D13+'7'!D13+'8'!D13+'9'!D13+'10'!D13+'11'!D13+'12'!D13 -> 0 | H11: المجموع الكلي للمدخول اعمال حرة او خاص او غيرها | K11: =E4*K10/1 -> #DIV/0! | P11: =E4*P10/1 -> #DIV/0!
C12: شهر 10
C13: شهر 11 | E13: المصاريف السنوية | K13: النسبة المئوية للراتب الشهري + المدخول الإضافي | P13: النسبة المئوية للراتب الشهري + المدخول الإضافي
C14: شهر 12 | E14: ='1'!D16+'2'!D16+'3'!D16+'4'!D16+'5'!D16+'6'!D16+'7'!D16+'8'!D16+'9'!D16+'10'!D16+'11'!D16+'12'!D16 -> 0 | H14: المجموع الكلي للراتب الزوجة 12 شهر | K14: الاستثمار | L14: ادخار الحج | M14: ادخار ( تأمين و تسجيل + ثياب العيد ) | N14: مصاريف متنوعة | P14: الاستثمار | R14: مصاريف متنوعة
C15: سلف و دين واقساط | E15: ='1'!D17+'2'!D17+'3'!D17+'4'!D17+'5'!D17+'6'!D17+'7'!D17+'8'!D17+'9'!D17+'10'!D17+'11'!D17+'12'!D17 -> 0 | H15: المجموع الكلي للمصاريف العائلة 12 شهر | K15: =E42/(E4+E9+E10+E11+E7+E8)*1 -> #DIV/0! | L15: =E39/(E4+E9+E10+E11+E7+E8)*1 -> #DIV/0! | M15: =E44/(E4+E9+E10+E11+E7+E8)*1 -> #DIV/0! | N15: =(E95-K16)/(E4+E9+E10+E11+E7+E8)*1 -> #DIV/0! | P15: =E42/(E4+E9+E10+E11+E7+E8)*1 -> #DIV/0! | R15: =(E95-K16)/(E4+E9+E10+E11+E7+E8)*1 -> #DIV/0!
E16: ='1'!AD108+'2'!AD108+'3'!AD108+'4'!AD108+'5'!AD108+'6'!AD108+'7'!AD108+'8'!AD108+'9'!AD108+'10'!AD108+'11'!AD108+'12'!AD108 -> 0 | H16: المجموع الكلي للأجار الشقة او المنزل 12 شهر | K16: =E42 -> 0 | L16: =E39 -> 0 | M16: =E44 -> 0 | N16: =(N15*(E4+E9+E10+E11+E7+E8))/1 -> #DIV/0! | P16: =E42 -> 0 | R16: =(N15*(E4+E9+E10+E11+E7+E8))/1 -> #DIV/0!
E17: ='1'!AG108+'2'!AG108+'3'!AG108+'4'!AG108+'5'!AG108+'6'!AG108+'7'!AG108+'8'!AG108+'9'!AG108+'10'!AG108+'10'!AG108+'12'!AG108 -> 0 | H17: المجموع الكلي لماچلة البيت 12 شهر | K17: =(N15+L15+K15+M15) -> #DIV/0! | M17: مجموع النسبة المئوية الكلي | P17: =(R15+P15) -> #DIV/0! | R17: مجموع النسبة المئوية الكلي
E18: ='1'!AD118+'2'!AD118+'3'!AD118+'4'!AD118+'5'!AD118+'6'!AD118+'7'!AD118+'8'!AD118+'9'!AD118+'10'!AD118+'11'!AD118+'12'!AD118 -> 0 | H18: المجموع الكلي لجميع الابيال الانترنت و خطوط الهاتف 12 شهر | K18: =K16+L16+N16+M16 -> #DIV/0! | P18: =P16+R16 -> #DIV/0!
E19: ='1'!AG118+'2'!AG118+'3'!AG118+'4'!AG118+'5'!AG118+'6'!AG118+'7'!AG118+'8'!AG118+'9'!AG118+'10'!AG118+'11'!AG118+'12'!AG118 -> 0 | H19: المجموع الكلي فواتير الكهرباء و الماء 12 شهر | K19: =1-K17 -> #DIV/0! | M19: المتبقي من الراتب ١٢ شهر | P19: =1-P17 -> #DIV/0! | R19: المتبقي من الراتب ١٢ شهر
E20: ='1'!D22+'2'!D22+'3'!D22+'4'!D22+'5'!D22+'6'!D22+'7'!D22+'8'!D22+'9'!D22+'10'!D22+'11'!D22+'12'!D22 -> 0 | H20: مصروفات أخرى 12 شهر | K20: =(E82*K19)/1 -> #DIV/0! | P20: =(E82*P19)/1 -> #DIV/0!
E21: ='1'!AD128+'2'!AD128+'3'!AD128+'4'!AD128+'5'!AD128+'6'!AD128+'7'!AD128+'8'!AD128+'9'!AD128+'10'!AD128+'11'!AD128+'12'!AD128 -> 0 | H21: المجموع الكلي للعلاج خلال السنة
E22: ='1'!AG128+'2'!AG128+'3'!AG128+'4'!AG128+'5'!AG128+'6'!AG128+'7'!AG128+'8'!AG128+'9'!AG128+'10'!AG128+'11'!AG128+'12'!AG128 -> 0 | H22: دفع مشتريات بطاقة الفيزا متنوعة ١
E23: ='1'!AD138+'2'!AD138+'3'!AD138+'4'!AD138+'5'!AD138+'6'!AD138+'7'!AD138+'8'!AD138+'9'!AD138+'10'!AD138+'11'!AD138+'12'!AD138 -> 0 | H23: دفع مشتريات بطاقة الفيزا متنوعة ٢
E24: ='1'!AG138+'2'!AG138+'3'!AG138+'4'!AG138+'5'!AG138+'6'!AG138+'7'!AG138+'8'!AG138+'9'!AG138+'10'!AG138+'11'!AG138+'12'!AG138 -> 0 | H24: دفع مشتريات بطاقة الفيزا متنوعة ٣
E25: ='1'!AD148+'2'!AD148+'3'!AD148+'4'!AD148+'5'!AD148+'6'!AD148+'7'!AD148+'8'!AD148+'9'!AD148+'10'!AD148+'11'!AD148+'12'!AD148 -> 0 | H25: المجموع الكلي للبترول لجميع السيارات 12 شهر
E26: ='1'!D28+'2'!D28+'3'!D28+'4'!D28+'5'!D28+'6'!D28+'7'!D28+'8'!D28+'9'!D28+'10'!D28+'11'!D28+'12'!D28 -> 0 | H26: المجموع الكلي للعامل التنظيف لجميع السيارات
E27: ='1'!AD158+'2'!AD158+'3'!AD158+'4'!AD158+'5'!AD158+'6'!AD158+'7'!AD158+'8'!AD158+'9'!AD158+'10'!AD158+'11'!AD158+'12'!AD158 -> 0 | H27: تصليح السيارة ( تبديل قطع غيار , صباغة و غيره)
E28: ='1'!AG158+'2'!AG158+'3'!AG158+'4'!AG158+'5'!AG158+'6'!AG158+'7'!AG158+'8'!AG158+'9'!AG158+'10'!AG158+'11'!AG158+'12'!AG158 -> 0
E29: ='1'!AD168+'2'!AD168+'3'!AD168+'4'!AD168+'5'!AD168+'6'!AD168+'7'!AD168+'8'!AD168+'9'!AD168+'10'!AD168+'11'!AD168+'12'!AD168 -> 0 | H29: تعديل او تصليح او ( إضافة في المنزل مثل شراء أغراض )
E30: ='1'!AG168+'2'!AG168+'3'!AG168+'4'!AG168+'5'!AG168+'6'!AG168+'7'!AG168+'8'!AG168+'9'!AG168+'10'!AG168+'11'!AG168+'12'!AG168 -> 0
E31: ='1'!AD178+'2'!AD178+'3'!AD178+'4'!AD178+'5'!AD178+'6'!AD178+'7'!AD178+'8'!AD178+'9'!AD178+'10'!AD178+'11'!AD178+'12'!AD178 -> 0 | H31: المجموع الكلي للتكاليف العيدميلاد
E32: ='1'!AG178+'2'!AG178+'3'!AG178+'4'!AG178+'5'!AG178+'6'!AG178+'7'!AG178+'8'!AG178+'9'!AG178+'10'!AG178+'11'!AG178+'12'!AG178 -> 0 | H32: المجموع الكلي للمدرسة الخاصة خلال السنة
E33: ='1'!AD188+'2'!AD188+'3'!AD188+'4'!AD188+'5'!AD188+'6'!AD188+'7'!AD188+'8'!AD188+'9'!AD188+'10'!AD188+'11'!AD188+'12'!AD188 -> 0 | H33: المجموع الكلي للروضة خلال السنة
E34: ='1'!AG188+'2'!AG188+'3'!AG188+'4'!AG188+'5'!AG188+'6'!AG188+'7'!AG188+'8'!AG188+'9'!AG188+'10'!AG188+'11'!AG188+'12'!AG188 -> 0 | H34: المجموع الكلي للجامعة خلال السنة
E35: ='1'!AD198+'2'!AD198+'3'!AD198+'4'!AD198+'5'!AD198+'6'!AD198+'7'!AD198+'8'!AD198+'9'!AD198+'10'!AD198+'11'!AD198+'12'!AD198 -> 0 | H35: المجموع الكلي للمواصلات المدارس او الجامعات خلال السنة
E36: ='1'!AG198+'2'!AG198+'3'!AG198+'4'!AG198+'5'!AG198+'6'!AG198+'7'!AG198+'8'!AG198+'9'!AG198+'10'!AG198+'11'!AG198+'12'!AG198 -> 0 | H36: المجموع الكلي للدروس التقوية للأطفال و الكبار خلال السنة
E37: العيد | F37: الملابس | G37: المدرسة | H37: المجموع الكلي للاحتياجات ألاطفال خلال السنة
E38: ='1'!AJ208+'2'!AJ208+'3'!AJ208+'4'!AJ208+'5'!AJ208+'6'!AJ208+'7'!AJ208+'8'!AJ208+'9'!AJ208+'10'!AJ208+'11'!AJ208+'12'!AJ208 -> 0 | F38: ='1'!AG208+'2'!AG208+'3'!AG208+'4'!AG208+'5'!AG208+'6'!AG208+'7'!AG208+'8'!AG208+'9'!AG208+'10'!AG208+'11'!AG208+'12'!AG208 -> 0 | G38: ='1'!AD208+'2'!AD208+'3'!AD208+'4'!AD208+'5'!AD208+'6'!AD208+'7'!AD208+'8'!AD208+'9'!AD208+'10'!AD208+'11'!AD208+'12'!AD208 -> 0
E39: ='1'!D42+'2'!D42+'3'!D42+'4'!D42+'5'!D42+'6'!D42+'7'!D42+'8'!D42+'9'!D42+'10'!D42+'11'!D42+'12'!D42+K39 -> 0 | H39: المجموع الكلي للادخار للحج خلال السنة
E40: ='1'!D43+'2'!D43+'3'!D43+'4'!D43+'5'!D43+'6'!D43+'7'!D43+'8'!D43+'9'!D43+'10'!D43+'11'!D43+'12'!D43 -> 0 | H40: المجموع الكلي للمساعدات انسانية خلال السنة
E41: ='1'!D44+'2'!D44+'3'!D44+'4'!D44+'5'!D44+'6'!D44+'7'!D44+'8'!D44+'9'!D44+'10'!D44+'11'!D44+'12'!D44 -> 0 | H41: المجموع الكلي للادخار ( جمعية ) خلال السنة
...

Sheet سلف و دين واقساط
G2: اخر تحديث بتاريخ
G4: تاربح البداء
G5: تاريخ الانتهاء
D6: العام الماضي | G6: هل الدين في السنة الحالية او العام الماضي , يرجى الاختيار
I7: المبلغ الذي تم دفعة العام الماضي
B8: اضغط هنا للرجوع الى الصفحة الرئيسية | G8: الاســــــــــــــــــــــــــــــــــــــــــــــــــــم : | H8: الدائن ( انا ماخذ سلف من احد )
F9: يرجى الاختيار | G9: المبلـــــــــــــغ الكلي لل :
D10: =D9-I9 -> 0 | G10: المبلغ الذي يجب دفعة: | H10: المدين ( ناس ماخذين مني سلف )
D11: ='1'!D54+'2'!D54+'3'!D54+'4'!D54+'5'!D54+'6'!D54+'7'!D54+'8'!D54+'9'!D54+'10'!D54+'11'!D54+'12'!D54 -> 0 | G11: تــــــــــــــــــــــم الدفـــــــــــــــــــع :
D12: =D10-D11 -> 0 | G12: المتبـــــــــــــــــــــــــــــــــــــــــــــــقي :
G14: تاربح البداء
G15: تاريخ الانتهاء
D16: السنة الحالية | G16: هل الدين في السنة الحالية او العام الماضي , يرجى الاختيار
I17: المبلغ الذي تم دفعة العام الماضي
G18: الاســــــــــــــــــــــــــــــــــــــــــــــــــــم : | H18: الدائن ( انا ماخذ سلف من احد )
B19: ذهاب الى | F19: يرجى الاختيار | G19: المبلـــــــــــــغ الكلي لل : | S19: =D10 -> 0 | V19: السنة الحالية ( يعني الراتب ينقص ) | Z19: ='سلف و دين واقساط'!D20 -> 0 | AC19: السنة الحالية ( يعني الراتب ينقص )
B20: شهر 1 | D20: =D19-I19 -> 0 | G20: المبلغ الذي يجب دفعة: | H20: المدين ( ناس ماخذين مني سلف ) | V20: العام الماضي ( ما ينحسب ) | AC20: العام الماضي ( ما ينحسب )
B21: شهر 2 | D21: ='1'!D61+'2'!D61+'3'!D61+'4'!D61+'5'!D61+'6'!D61+'7'!D61+'8'!D61+'9'!D61+'10'!D61+'11'!D61+'12'!D61 -> 0 | G21: تــــــــــــــــــــــم الدفـــــــــــــــــــع :
B22: شهر 3 | D22: =D20-D21 -> 0 | G22: المتبـــــــــــــــــــــــــــــــــــــــــــــــقي : | U22: =VLOOKUP('سلف و دين واقساط'!D6,T24:U26,2) -> 0 | V22: مهم | AB22: =VLOOKUP('سلف و دين واقساط'!D16,AA24:AB26,2) -> 0 | AC22: مهم
B23: شهر 4
B24: شهر 5 | G24: تاربح البداء | T24: السنة الحالية | U24: =-S19 -> 0 | AA24: السنة الحالية | AB24: =-Z19 -> 0
B25: شهر 6 | G25: تاريخ الانتهاء
B26: شهر 7 | D26: السنة الحالية | G26: هل الدين في السنة الحالية او العام الماضي , يرجى الاختيار | T26: العام الماضي | U26: 0 | AA26: العام الماضي | AB26: 0
B27: شهر 8 | I27: المبلغ الذي تم دفعة العام الماضي
B28: شهر 9 | G28: الاســــــــــــــــــــــــــــــــــــــــــــــــــــم : | H28: الدائن ( انا ماخذ سلف من احد )
B29: شهر 10 | F29: يرجى الاختيار | G29: المبلـــــــــــــغ الكلي لل :
B30: شهر 11 | D30: =D29-I29 -> 0 | G30: المبلغ الذي يجب دفعة: | H30: المدين ( ناس ماخذين مني سلف ) | S30: ='سلف و دين واقساط'!D30 -> 0 | V30: السنة الحالية ( يعني الراتب ينقص ) | Z30: ='سلف و دين واقساط'!D40 -> 0 | AC30: السنة الحالية ( يعني الراتب ينقص )
B31: شهر 12 | D31: ='1'!J54+'2'!J54+'3'!J54+'4'!J54+'5'!J54+'6'!J54+'7'!J54+'8'!J54+'9'!J54+'10'!J54+'11'!J54+'12'!J54 -> 0 | G31: تــــــــــــــــــــــم الدفـــــــــــــــــــع : | V31: العام الماضي ( ما ينحسب ) | AC31: العام الماضي ( ما ينحسب )
D32: =D30-D31 -> 0 | G32: المتبـــــــــــــــــــــــــــــــــــــــــــــــقي :
G34: تاربح البداء | U34: =VLOOKUP('سلف و دين واقساط'!D26,T36:U37,2) -> 0 | V34: مهم | AB34: =VLOOKUP('سلف و دين واقساط'!D36,AA36:AB37,2) -> 0 | AC34: مهم
G35: تاريخ الانتهاء
D36: السنة الحالية | G36: هل الدين في السنة الحالية او العام الماضي , يرجى الاختيار | T36: السنة الحالية | U36: =-S30 -> 0 | AA36: السنة الحالية | AB36: =-Z30 -> 0
I37: المبلغ الذي تم دفعة العام الماضي | T37: العام الماضي | U37: 0 | AA37: العام الماضي | AB37: 0
G38: الاســــــــــــــــــــــــــــــــــــــــــــــــــــم : | H38: الدائن ( انا ماخذ سلف من احد )
F39: مدين | G39: المبلـــــــــــــغ الكلي لل :
D40: =D39-I39 -> 0 | G40: المبلغ الذي يجب دفعة: | H40: المدين ( ناس ماخذين مني سلف )
D41: ='1'!J61+'2'!J61+'3'!J61+'4'!J61+'5'!J61+'6'!J61+'7'!J61+'8'!J61+'9'!J61+'10'!J61+'11'!J61+'12'!J61 -> 0 | G41: تــــــــــــــــــــــم الدفـــــــــــــــــــع :
D42: =D40-D41 -> 0 | G42: المتبـــــــــــــــــــــــــــــــــــــــــــــــقي :
G44: تاربح البداء
G45: تاريخ الانتهاء
...

Sheet 1
G2: اخر تحديث بتاريخ | S2: بدون اقتطاع ادخار + الحج
D4: جدول شهر 1 | N4: النسبة المئوية للراتب الشهري فقط | S4: النسبة المئوية للراتب الشهري فقط
N5: الاستثمار | O5: ادخار الحج | P5: ادخار ( تأمين و تسجيل + ثياب العيد ) + للسفر | Q5: مصاريف متنوعة | S5: الاستثمار | U5: مصاريف متنوعة
B6: اضغط هنا للرجوع الى الصفحة الرئيسية | G6: راتب الشهري | I6: * | N6: =(DF30+DH30+DJ30+DF41+DH41+DJ41)/(D6+U83+AA83+AA89+U89)*1 -> #DIV/0! | O6: =(CW30+CY30+DA30+CW41+CY41+DA41)/(D6+U83+AA83+AA89+U89)*1 -> #DIV/0! | P6: =(DO30+DQ30+DS30+DO41+DQ41+DS41+DO8+DQ8+DS8+DO19+DQ19+DS19)/(D6+U83+AA83+AA89+U89)*1 -> #DIV/0! | Q6: =(D103-N7)/(D6+U83+AA83+AA89+U89)*1 -> #DIV/0! | S6: =(DF30+DH30+DJ30+DF41+DH41+DJ41)/(D6+U83+AA83+AA89+U89)*1 -> #DIV/0! | U6: =(D103-N7)/(D6+U83+AA83+AA89+U89)*1 -> #DIV/0!
N7: =DF30+DH30+DJ30+DF41+DH41+DJ41 -> 0 | O7: =CW30+CY30+DA30+CW41+CY41+DA41 -> 0 | P7: =DO30+DQ30+DS30+DO41+DQ41+DS41+DO8+DQ8+DS8+DO19+DQ19+DS19 -> 0 | Q7: =(D6+U83+AA83+AA89+U89)*Q6/1 -> #DIV/0! | S7: =DF30+DH30+DJ30+DF41+DH41+DJ41 -> 0 | U7: =(D6+U83+AA83+AA89+U89)*Q6/1 -> #DIV/0! | AC7: علاج 1 | AE7: علاج 3 | AG7: علاج 5 | AL7: اجار الشقة ١٫١ | AN7: اجار الشقة ١٫٣ | AP7: اجار الشقة ١٫٥ | AU7: ماجلة البيت ١٫١ | AW7: ماجلة البيت ١٫٣ | AY7: ماجلة البيت ١٫٥ | BD7: جميع الابيال ١٫١ | BF7: جميع الابيال ١٫٣ | BH7: جميع الابيال ١٫٥ | BM7: بيل الكهرباء ١٫١ | BO7: بيل الكهرباء ١٫٣ | BQ7: بيل الكهرباء ١٫٥ | BV7: بترول الجميع ١٫١ | BX7: بترول الجميع ١٫٣ | BZ7: بترول الجميع ١٫٥ | CE7: قسط بطاقة الفيزا البنكية 1.1 | CG7: قسط بطاقة الفيزا البنكية 1.3 | CI7: قسط بطاقة الفيزا البنكية 1.5 | CN7: راتب الزوجة 1.1 | CP7: راتب الزوجة 1.3 | CR7: راتب الزوجة 1.5 | CW7: عامل التنظيف لجميع السيارات 1.1 | CY7: عامل التنظيف لجميع السيارات 1.3 | DA7: عامل التنظيف لجميع السيارات 1.5 | DF7: جمعية 1.1 | DH7: جمعية 1.3 | DJ7: جمعية 1.5 | DO7: ادخار ( تأمين و تسجيل + ثياب العيد + الروضة ) 1.1 | DQ7: ادخار ( تأمين و تسجيل + ثياب العيد + الروضة ) 1.3 | DS7: ادخار ( تأمين و تسجيل + ثياب العيد + الروضة ) 1.5
D8: دخل ايضافي كل شهر | N8: =(Q6+O6+N6+P6) -> #DIV/0! | P8: مجموع النسبة المئوية الكلي | S8: =(U6+S6) -> #DIV/0! | U8: مجموع النسبة المئوية الكلي | AC8: =VLOOKUP(G23,AC9:AD15,2,FALSE) -> 0 | AE8: =VLOOKUP(G23,AE9:AF15,2,FALSE) -> 0 | AG8: =VLOOKUP(G23,AG9:AH15,2,FALSE) -> 0 | AL8: =VLOOKUP(G18,AL9:AM15,2,FALSE) -> 0 | AN8: =VLOOKUP(G18,AN9:AO15,2,FALSE) -> 0 | AP8: =VLOOKUP(G18,AP9:AQ15,2,FALSE) -> 0 | AU8: =VLOOKUP(G19,AU9:AV15,2,FALSE) -> 0 | AW8: =VLOOKUP(G19,AW9:AX15,2,FALSE) -> 0 | AY8: =VLOOKUP(G19,AY9:AZ15,2,FALSE) -> 0 | BD8: =VLOOKUP(G20,BD9:BE15,2,FALSE) -> 0 | BF8: =VLOOKUP(G20,BF9:BG15,2,FALSE) -> 0 | BH8: =VLOOKUP(G20,BH9:BI15,2,FALSE) -> 0 | BM8: =VLOOKUP(G21,BM9:BN15,2,FALSE) -> 0 | BO8: =VLOOKUP(G21,BO9:BP15,2,FALSE) -> 0 | BQ8: =VLOOKUP(G21,BQ9:BR15,2,FALSE) -> 0 | BV8: =VLOOKUP(G27,BV9:BW15,2,FALSE) -> 0 | BX8: =VLOOKUP(G27,BX9:BY15,2,FALSE) -> 0 | BZ8: =VLOOKUP(G27,BZ9:CA15,2,FALSE) -> 0 | CE8: =VLOOKUP(H68,CE9:CF15,2,FALSE) -> 0 | CG8: =VLOOKUP(H68,CG9:CH15,2,FALSE) -> 0 | CI8: =VLOOKUP(H68,CI9:CJ15,2,FALSE) -> 0 | CN8: =VLOOKUP(G16,CN9:CO15,2,FALSE) -> 0 | CP8: =VLOOKUP(G16,CP9:CQ15,2,FALSE) -> 0 | CR8: =VLOOKUP(G16,CR9:CS15,2,FALSE) -> 0 | CW8: =VLOOKUP(G28,CW9:CX15,2,FALSE) -> 0 | CY8: =VLOOKUP(G28,CY9:CZ15,2,FALSE) -> 0 | DA8: =VLOOKUP(G28,DA9:DB15,2,FALSE) -> 0 | DF8: =VLOOKUP(G44,DF9:DG15,2,FALSE) -> 0 | DH8: =VLOOKUP(G44,DH9:DI15,2,FALSE) -> 0 | DJ8: =VLOOKUP(G44,DJ9:DK15,2,FALSE) -> 0 | DO8: =VLOOKUP(G47,DO9:DP15,2,FALSE) -> 0 | DQ8: =VLOOKUP(G47,DQ9:DR15,2,FALSE) -> 0 | DS8: =VLOOKUP(G47,DS9:DT15,2,FALSE) -> 0
G9: غلاء المعيشة | I9: * | N9: =N7+Q7+O7+P7 -> #DIV/0! | S9: =S7+U7 -> #DIV/0! | AC9: NBK | AD9: =D23 -> 0 | AE9: NBK | AG9: NBK | AL9: NBK | AM9: =D18 -> 0 | AN9: NBK | AP9: NBK | AU9: NBK | AV9: =D19 -> 0 | AW9: NBK | AY9: NBK | BD9: NBK | BE9: =D20 -> 0 | BF9: NBK | BH9: NBK | BM9: NBK | BN9: =D21 -> 0 | BO9: NBK | BQ9: NBK | BV9: NBK | BW9: =D27 -> 0 | BX9: NBK | BZ9: NBK | CE9: NBK | CF9: =D67 -> 0 | CG9: NBK | CI9: NBK | CN9: NBK | CO9: =D16 -> 0 | CP9: NBK | CR9: NBK | CW9: NBK | CX9: =D28 -> 0 | CY9: NBK | DA9: NBK | DF9: NBK | DG9: =D44 -> 0 | DH9: NBK | DJ9: NBK | DO9: NBK | DP9: =D47 -> 0 | DQ9: NBK | DS9: NBK
G10: علاوة إسكان | I10: * | N10: =1-N8 -> #DIV/0! | P10: المتبقي من الراتب | S10: =1-S8 -> #DIV/0! | U10: المتبقي من الراتب | AC10: ILA | AE10: ILA | AG10: ILA | AL10: ILA | AN10: ILA | AP10: ILA | AU10: ILA | AW10: ILA | AY10: ILA | BD10: ILA | BF10: ILA | BH10: ILA | BM10: ILA | BO10: ILA | BQ10: ILA | BV10: ILA | BX10: ILA | BZ10: ILA | CE10: ILA | CG10: ILA | CI10: ILA | CN10: ILA | CP10: ILA | CR10: ILA | CW10: ILA | CY10: ILA | DA10: ILA | DF10: ILA | DH10: ILA | DJ10: ILA | DO10: ILA | DQ10: ILA | DS10: ILA
G11: نعــــم بتــــــــــــنزل ذي الشهر | H11: دعم اللحوم كل ثلاث شهور | I11: * | N11: =((D6+U83+AA83+AA89+U89)*N10)/1 -> #DIV/0! | S11: =((D6+U83+AA83+AA89+U89)*S10)/1 -> #DIV/0! | AC11: BBK | AE11: BBK | AF11: =D23 -> 0 | AG11: BBK | AL11: BBK | AN11: BBK | AO11: =D18 -> 0 | AP11: BBK | AU11: BBK | AW11: BBK | AX11: =D19 -> 0 | AY11: BBK | BD11: BBK | BF11: BBK | BG11: =D20 -> 0 | BH11: BBK | BM11: BBK | BO11: BBK | BP11: =D21 -> 0 | BQ11: BBK | BV11: BBK | BX11: BBK | BY11: =D27 -> 0 | BZ11: BBK | CE11: BBK | CG11: BBK | CH11: =D67 -> 0 | CI11: BBK | CN11: BBK | CP11: BBK | CQ11: =D16 -> 0 | CR11: BBK | CW11: BBK | CY11: BBK | CZ11: =D28 -> 0 | DA11: BBK | DF11: BBK | DH11: BBK | DI11: =D44 -> 0 | DJ11: BBK | DO11: BBK | DQ11: BBK | DR11: =D47 -> 0 | DS11: BBK
G12: مساعدات خيرية | I12: * | AC12: MEEM | AE12: MEEM | AG12: MEEM | AL12: MEEM | AN12: MEEM | AP12: MEEM | AU12: MEEM | AW12: MEEM | AY12: MEEM | BD12: MEEM | BF12: MEEM | BH12: MEEM | BM12: MEEM | BO12: MEEM | BQ12: MEEM | BV12: MEEM | BX12: MEEM | BZ12: MEEM | CE12: MEEM | CG12: MEEM | CI12: MEEM | CN12: MEEM | CP12: MEEM | CR12: MEEM | CW12: MEEM | CY12: MEEM | DA12: MEEM | DF12: MEEM | DH12: MEEM | DJ12: MEEM | DO12: MEEM | DQ12: MEEM | DS12: MEEM
G13: مدخول اعمال حرة او خاص او جمعية او غيرها | I13: * | N13: النسبة المئوية للراتب الشهري + المدخول الإضافي | S13: النسبة المئوية للراتب الشهري + المدخول الإضافي | AC13: NBB | AE13: NBB | AG13: NBB | AH13: =D23 -> 0 | AL13: NBB | AN13: NBB | AP13: NBB | AQ13: =D18 -> 0 | AU13: NBB | AW13: NBB | AY13: NBB | AZ13: =D19 -> 0 | BD13: NBB | BF13: NBB | BH13: NBB | BI13: =D20 -> 0 | BM13: NBB | BO13: NBB | BQ13: NBB | BR13: =D21 -> 0 | BV13: NBB | BX13: NBB | BZ13: NBB | CA13: =D27 -> 0 | CE13: NBB | CG13: NBB | CI13: NBB | CJ13: =D67 -> 0 | CN13: NBB | CP13: NBB | CR13: NBB | CS13: =D16 -> 0 | CW13: NBB | CY13: NBB | DA13: NBB | DB13: =D28 -> 0 | DF13: NBB | DH13: NBB | DJ13: NBB | DK13: =D44 -> 0 | DO13: NBB | DQ13: NBB | DS13: NBB | DT13: =D47 -> 0
E14: ثياب العيد | G14: ركز اهني هل يوجد عيد في ذي الشهر حق لثياب او العيادي | I14: مجرد ملاحظة و مارح ينحسب , اختار البنك | K14: مــــــــــــــلاحظات | N14: الاستثمار | O14: ادخار الحج | P14: ادخار ( تأمين و تسجيل + ثياب العيد ) + للسفر | Q14: مصاريف متنوع | S14: الاستثمار | U14: مصاريف متنوع | AC14: بطاقة صراف الالي | AE14: بطاقة صراف الالي | AG14: بطاقة صراف الالي | AL14: بطاقة صراف الالي | AN14: بطاقة صراف الالي | AP14: بطاقة صراف الالي | AU14: بطاقة صراف الالي | AW14: بطاقة صراف الالي | AY14: بطاقة صراف الالي | BD14: بطاقة صراف الالي | BF14: بطاقة صراف الالي | BH14: بطاقة صراف الالي | BM14: بطاقة صراف الالي | BO14: بطاقة صراف الالي | BQ14: بطاقة صراف الالي | BV14: بطاقة صراف الالي | BX14: بطاقة صراف الالي | BZ14: بطاقة صراف الالي | CE14: بطاقة صراف الالي | CG14: بطاقة صراف الالي | CI14: بطاقة صراف الالي | CN14: بطاقة صراف الالي | CP14: بطاقة صراف الالي | CR14: بطاقة صراف الالي | CW14: بطاقة صراف الالي | CY14: بطاقة صراف الالي | DA14: بطاقة صراف الالي | DF14: بطاقة صراف الالي | DH14: بطاقة صراف الالي | DJ14: بطاقة صراف الالي | DO14: بطاقة صراف الالي | DQ14: بطاقة صراف الالي | DS14: بطاقة صراف الالي
B15: ذهاب الى | D15: المصاريف الشهرية وتوزيعها | N15: =(DF30+DH30+DJ30+DF41+DH41+DJ41)/(D6+D9+D10+D11+D12+D13+U83+AA83+AA89+U89)*1 -> #DIV/0! | O15: =(CW30+CY30+DA30+CW41+CY41+DA41)/(D6+D9+D10+D11+D12+D13+U83+AA83+AA89+U89)*1 -> #DIV/0! | P15: =(DO30+DQ30+DS30+DO41+DQ41+DS41+DO8+DQ8+DS8+DO19+DQ19+DS19)/(D6+D9+D10+D11+D12+D13+U83+AA83+AA89+U89)*1 -> #DIV/0! | Q15: =(D103-N7)/(D6+D9+D10+D11+D12+D13+U83+AA83+AA89+U89)*1 -> #DIV/0! | S15: =(DF30+DH30+DJ30+DF41+DH41+DJ41)/(D6+D9+D10+D11+D12+D13+U83+AA83+AA89+U89)*1 -> #DIV/0! | U15: =(D103-N7)/(D6+D9+D10+D11+D12+D13+U83+AA83+AA89+U89)*1 -> #DIV/0! | AC15: غير محسوب ذي الشهر | AE15: غير محسوب ذي الشهر | AG15: غير محسوب ذي الشهر | AL15: غير محسوب ذي الشهر | AN15: غير محسوب ذي الشهر | AP15: غير محسوب ذي الشهر | AU15: غير محسوب ذي الشهر | AW15: غير محسوب ذي الشهر | AY15: غير محسوب ذي الشهر | BD15: غير محسوب ذي الشهر | BF15: غير محسوب ذي الشهر | BH15: غير محسوب ذي الشهر | BM15: غير محسوب ذي الشهر | BO15: غير محسوب ذي الشهر | BQ15: غير محسوب ذي الشهر | BV15: غير محسوب ذي الشهر | BX15: غير محسوب ذي الشهر | BZ15: غير محسوب ذي الشهر | CE15: غير محسوب ذي الشهر | CG15: غير محسوب ذي الشهر | CI15: غير محسوب ذي الشهر | CN15: غير محسوب ذي الشهر | CP15: غير محسوب ذي الشهر | CR15: غير محسوب ذي الشهر | CW15: غير محسوب ذي الشهر | CY15: غير محسوب ذي الشهر | DA15: غير محسوب ذي الشهر | DF15: غير محسوب ذي الشهر | DH15: غير محسوب ذي الشهر | DJ15: غير محسوب ذي الشهر | DO15: غير محسوب ذي الشهر | DQ15: غير محسوب ذي الشهر | DS15: غير محسوب ذي الشهر
B16: شهر 1 | G16: بطاقة صراف الالي | H16: راتب الزوجة | I16: - | N16: =DF30+DH30+DJ30+DF41+DH41+DJ41 -> 0 | O16: =CW30+CY30+DA30+CW41+CY41+DA41 -> 0 | P16: =DO30+DQ30+DS30+DO41+DQ41+DS41+DO8+DQ8+DS8+DO19+DQ19+DS19 -> 0 | Q16: =(D6+D9+D10+D11+D12+D13+U83+AA83+AA89+U89)*Q15/1 -> #DIV/0! | S16: =DF30+DH30+DJ30+DF41+DH41+DJ41 -> 0 | U16: =(D6+D9+D10+D11+D12+D13+U83+AA83+AA89+U89)*Q15/1 -> #DIV/0!
B17: شهر 2 | G17: بطاقة صراف الالي | H17: مصروف العائلة | I17: - | N17: =(Q15+O15+N15+P15) -> #DIV/0! | P17: مجموع النسبة المئوية الكلي | S17: =(U15+S15) -> #DIV/0! | U17: مجموع النسبة المئوية الكلي
B18: شهر 3 | G18: بطاقة صراف الالي | H18: أجار الشقة او المنزل | I18: - | N18: =N16+O16+Q16+P16 -> #DIV/0! | S18: =S16+U16 -> #DIV/0! | AC18: علاج 2 | AE18: علاج 4 | AG18: علاج 6 | AI18: علاج 7 | AL18: اجار الشقة ١٫٢ | AN18: اجار الشقة ١٫٤ | AP18: اجار الشقة ١٫٦ | AR18: اجار الشقة ١٫٧ | AU18: ماجلة البيت ١٫٢ | AW18: ماجلة البيت ١٫٤ | AY18: ماجلة البيت ١٫٦ | BA18: ماجلة البيت ١٫٧ | BD18: جميع الابيال ١٫٢ | BF18: جميع الابيال ١٫٤ | BH18: جميع الابيال ١٫٦ | BJ18: جميع الابيال ١٫٧ | BM18: بيل الكهرباء ١٫٢ | BO18: بيل الكهرباء ١٫٤ | BQ18: بيل الكهرباء ١٫٦ | BS18: بيل الكهرباء ١٫٧ | BV18: بترول الجميع ١٫٢ | BX18: بترول الجميع ١٫٤ | BZ18: بترول الجميع ١٫٦ | CB18: بترول الجميع ١٫٧ | CE18: قسط بطاقة الفيزا البنكية 1.2 | CG18: قسط بطاقة الفيزا البنكية 1.4 | CI18: قسط بطاقة الفيزا البنكية 1.6 | CK18: قسط بطاقة الفيزا البنكية 1.7 | CN18: راتب الزوجة 1.2 | CP18: راتب الزوجة 1.4 | CR18: راتب الزوجة 1.6 | CT18: راتب الزوجة 1.7 | CW18: عامل التنظيف لجميع السيارات 1.2 | CY18: عامل التنظيف لجميع السيارات 1.4 | DA18: عامل التنظيف لجميع السيارات 1.6 | DC18: عامل التنظيف لجميع السيارات 1.7 | DF18: جمعية 1.2 | DH18: جمعية 1.4 | DJ18: جمعية 1.6 | DL18: جمعية 1.7 | DO18: ادخار ( تأمين و تسجيل + ثياب العيد + الروضة ) 1.2 | DQ18: ادخار ( تأمين و تسجيل + ثياب العيد + الروضة ) 1.4 | DS18: ادخار ( تأمين و تسجيل + ثياب العيد + الروضة ) 1.6 | DU18: ادخار ( تأمين و تسجيل + ثياب العيد + الروضة ) 1.7
B19: شهر 4 | G19: بطاقة صراف الالي | H19: ماچلة البيت | I19: - | N19: =1-N17 -> #DIV/0! | P19: المتبقي من الراتب | S19: =1-S17 -> #DIV/0! | U19: المتبقي من الراتب | AC19: =VLOOKUP(G23,AC20:AD26,2,FALSE) -> 0 | AE19: =VLOOKUP(G23,AE20:AF26,2,FALSE) -> 0 | AG19: =VLOOKUP(G23,AG20:AH26,2,FALSE) -> 0 | AI19: =VLOOKUP(G23,AI20:AJ26,2,FALSE) -> 0 | AL19: =VLOOKUP(G18,AL20:AM26,2,FALSE) -> 0 | AN19: =VLOOKUP(G18,AN20:AO26,2,FALSE) -> 0 | AP19: =VLOOKUP(G18,AP20:AQ26,2,FALSE) -> 0 | AR19: =VLOOKUP(G18,AR20:AS26,2,FALSE) -> 0 | AU19: =VLOOKUP(G19,AU20:AV26,2,FALSE) -> 0 | AW19: =VLOOKUP(G19,AW20:AX26,2,FALSE) -> 0 | AY19: =VLOOKUP(G19,AY20:AZ26,2,FALSE) -> 0 | BA19: =VLOOKUP(G19,BA20:BB26,2,FALSE) -> 0 | BD19: =VLOOKUP(G20,BD20:BE26,2,FALSE) -> 0 | BF19: =VLOOKUP(G20,BF20:BG26,2,FALSE) -> 0 | BH19: =VLOOKUP(G20,BH20:BI26,2,FALSE) -> 0 | BJ19: =VLOOKUP(G20,BJ20:BK26,2,FALSE) -> 0 | BM19: =VLOOKUP(G21,BM20:BN26,2,FALSE) -> 0 | BO19: =VLOOKUP(G21,BO20:BP26,2,FALSE) -> 0 | BQ19: =VLOOKUP(G21,BQ20:BR26,2,FALSE) -> 0 | BS19: =VLOOKUP(G21,BS20:BT26,2,FALSE) -> 0 | BV19: =VLOOKUP(G27,BV20:BW26,2,FALSE) -> 0 | BX19: =VLOOKUP(G27,BX20:BY26,2,FALSE) -> 0 | BZ19: =VLOOKUP(G27,BZ20:CA26,2,FALSE) -> 0 | CB19: =VLOOKUP(G27,CB20:CC26,2,FALSE) -> 0 | CE19: =VLOOKUP(H68,CE20:CF26,2,FALSE) -> 0 | CG19: =VLOOKUP(H68,CG20:CH26,2,FALSE) -> 0 | CI19: =VLOOKUP(H68,CI20:CJ26,2,FALSE) -> 0 | CK19: =VLOOKUP(H68,CK20:CL26,2,FALSE) -> 0 | CN19: =VLOOKUP(G16,CN20:CO26,2,FALSE) -> 0 | CP19: =VLOOKUP(G16,CP20:CQ26,2,FALSE) -> 0 | CR19: =VLOOKUP(G16,CR20:CS26,2,FALSE) -> 0 | CT19: =VLOOKUP(G16,CT20:CU26,2,FALSE) -> 0 | CW19: =VLOOKUP(G28,CW20:CX26,2,FALSE) -> 0 | CY19: =VLOOKUP(G28,CY20:CZ26,2,FALSE) -> 0 | DA19: =VLOOKUP(G28,DA20:DB26,2,FALSE) -> 0 | DC19: =VLOOKUP(G28,DC20:DD26,2,FALSE) -> 0 | DF19: =VLOOKUP(G44,DF20:DG26,2,FALSE) -> 0 | DH19: =VLOOKUP(G44,DH20:DI26,2,FALSE) -> 0 | DJ19: =VLOOKUP(G44,DJ20:DK26,2,FALSE) -> 0 | DL19: =VLOOKUP(G44,DL20:DM26,2,FALSE) -> 0 | DO19: =VLOOKUP(G47,DO20:DP26,2,FALSE) -> 0 | DQ19: =VLOOKUP(G47,DQ20:DR26,2,FALSE) -> 0 | DS19: =VLOOKUP(G47,DS20:DT26,2,FALSE) -> 0 | DU19: =VLOOKUP(G47,DU20:DV26,2,FALSE) -> 0
B20: شهر 5 | G20: بطاقة صراف الالي | H20: جميع الابيال الانترنت و خطوط الهاتف | I20: - | N20: =(D6+D9+D10+D11+D12+D13+U83+AA83+AA89+U89)*N19/1 -> #DIV/0! | S20: =(D6+D9+D10+D11+D12+D13+U83+AA83+AA89+U89)*S19/1 -> #DIV/0! | AC20: NBK | AE20: NBK | AG20: NBK | AI20: NBK | AL20: NBK | AN20: NBK | AP20: NBK | AR20: NBK | AU20: NBK | AW20: NBK | AY20: NBK | BA20: NBK | BD20: NBK | BF20: NBK | BH20: NBK | BJ20: NBK | BM20: NBK | BO20: NBK | BQ20: NBK | BS20: NBK | BV20: NBK | BX20: NBK | BZ20: NBK | CB20: NBK | CE20: NBK | CG20: NBK | CI20: NBK | CK20: NBK | CN20: NBK | CP20: NBK | CR20: NBK | CT20: NBK | CW20: NBK | CY20: NBK | DA20: NBK | DC20: NBK | DF20: NBK | DH20: NBK | DJ20: NBK | DL20: NBK | DO20: NBK | DQ20: NBK | DS20: NBK | DU20: NBK
B21: شهر 6 | G21: بطاقة صراف الالي | H21: بيل الكهرباء و الماء | I21: - | AC21: ILA | AD21: =D23 -> 0 | AE21: ILA | AG21: ILA | AI21: ILA | AL21: ILA | AM21: =D18 -> 0 | AN21: ILA | AP21: ILA | AR21: ILA | AU21: ILA | AV21: =D19 -> 0 | AW21: ILA | AY21: ILA | BA21: ILA | BD21: ILA | BE21: =D20 -> 0 | BF21: ILA | BH21: ILA | BJ21: ILA | BM21: ILA | BN21: =D21 -> 0 | BO21: ILA | BQ21: ILA | BS21: ILA | BV21: ILA | BW21: =D27 -> 0 | BX21: ILA | BZ21: ILA | CB21: ILA | CE21: ILA | CF21: =D67 -> 0 | CG21: ILA | CI21: ILA | CK21: ILA | CN21: ILA | CO21: =D16 -> 0 | CP21: ILA | CR21: ILA | CT21: ILA | CW21: ILA | CX21: =D28 -> 0 | CY21: ILA | DA21: ILA | DC21: ILA | DF21: ILA | DG21: =D44 -> 0 | DH21: ILA | DJ21: ILA | DL21: ILA | DO21: ILA | DP21: =D47 -> 0 | DQ21: ILA | DS21: ILA | DU21: ILA
B22: شهر 7 | G22: بطاقة صراف الالي | H22: مصروفات أخرى | I22: - | O22: مجموع الكلي الاقتطاعات للبطائق و حسابي المصرفي | AC22: BBK | AE22: BBK | AG22: BBK | AI22: BBK | AL22: BBK | AN22: BBK | AP22: BBK | AR22: BBK | AU22: BBK | AW22: BBK | AY22: BBK | BA22: BBK | BD22: BBK | BF22: BBK | BH22: BBK | BJ22: BBK | BM22: BBK | BO22: BBK | BQ22: BBK | BS22: BBK | BV22: BBK | BX22: BBK | BZ22: BBK | CB22: BBK | CE22: BBK | CG22: BBK | CI22: BBK | CK22: BBK | CN22: BBK | CP22: BBK | CR22: BBK | CT22: BBK | CW22: BBK | CY22: BBK | DA22: BBK | DC22: BBK | DF22: BBK | DH22: BBK | DJ22: BBK | DL22: BBK | DO22: BBK | DQ22: BBK | DS22: BBK | DU22: BBK
B23: شهر 8 | G23: بطاقة صراف الالي | H23: علاج | I23: - | O23: اسم البنك | P23: السعر | AC23: MEEM | AE23: MEEM | AF23: =D23 -> 0 | AG23: MEEM | AI23: MEEM | AL23: MEEM | AN23: MEEM | AO23: =D18 -> 0 | AP23: MEEM | AR23: MEEM | AU23: MEEM | AW23: MEEM | AX23: =D19 -> 0 | AY23: MEEM | BA23: MEEM | BD23: MEEM | BF23: MEEM | BG23: =D20 -> 0 | BH23: MEEM | BJ23: MEEM | BM23: MEEM | BO23: MEEM | BP23: =D21 -> 0 | BQ23: MEEM | BS23: MEEM | BV23: MEEM | BX23: MEEM | BY23: =D27 -> 0 | BZ23: MEEM | CB23: MEEM | CE23: MEEM | CG23: MEEM | CH23: =D67 -> 0 | CI23: MEEM | CK23: MEEM | CN23: MEEM | CP23: MEEM | CQ23: =D16 -> 0 | CR23: MEEM | CT23: MEEM | CW23: MEEM | CY23: MEEM | CZ23: =D28 -> 0 | DA23: MEEM | DC23: MEEM | DF23: MEEM | DH23: MEEM | DI23: =D44 -> 0 | DJ23: MEEM | DL23: MEEM | DO23: MEEM | DQ23: MEEM | DR23: =D47 -> 0 | DS23: MEEM | DU23: MEEM
B24: شهر 9 | G24: غير محسوب ذي الشهر | H24: دفع مشتريات بطاقة الفيزا متنوعة ١ | I24: - | O24: NBK | P24: =AC75+AC84+AC93+AC8+AL8+AU8+BD8+BM8+BV8+AC30+AL30+AU30+BD30+AC52+AL52+AU52+BD52+BM52+BM30+BV30+BV52+CE8+CE30+CE52+CN8+CN30+CN52+CW8+CW30+CW52+DF8+DF30+DF52+DO8+DO30 -> 0 | AC24: NBB | AE24: NBB | AG24: NBB | AI24: NBB | AL24: NBB | AN24: NBB | AP24: NBB | AR24: NBB | AU24: NBB | AW24: NBB | AY24: NBB | BA24: NBB | BD24: NBB | BF24: NBB | BH24: NBB | BJ24: NBB | BM24: NBB | BO24: NBB | BQ24: NBB | BS24: NBB | BV24: NBB | BX24: NBB | BZ24: NBB | CB24: NBB | CE24: NBB | CG24: NBB | CI24: NBB | CK24: NBB | CN24: NBB | CP24: NBB | CR24: NBB | CT24: NBB | CW24: NBB | CY24: NBB | DA24: NBB | DC24: NBB | DF24: NBB | DH24: NBB | DJ24: NBB | DL24: NBB | DO24: NBB | DQ24: NBB | DS24: NBB | DU24: NBB
B25: شهر 10 | G25: غير محسوب ذي الشهر | H25: دفع مشتريات بطاقة الفيزا متنوعة ٢ | I25: - | O25: ILA | P25: =AE75+AE84+AE93+AC19+AL19+AU19+BD19+BM19+BV19+AC41+AL41+AU41+BD41+AC63+AL63+AU63+BD63+BM63+BM41+BV41+BV63+CE19+CE41+CE63+CN19+CN41+CN63+CW19+CW41+CW63+DF19+DF41+DF63+DO19+DO41 -> 0 | AC25: بطاقة صراف الالي | AE25: بطاقة صراف الالي | AG25: بطاقة صراف الالي | AH25: =D23 -> 0 | AI25: بطاقة صراف الالي | AL25: بطاقة صراف الالي | AN25: بطاقة صراف الالي | AP25: بطاقة صراف الالي | AQ25: =D18 -> 0 | AR25: بطاقة صراف الالي | AU25: بطاقة صراف الالي | AW25: بطاقة صراف الالي | AY25: بطاقة صراف الالي | AZ25: =D19 -> 0 | BA25: بطاقة صراف الالي | BD25: بطاقة صراف الالي | BF25: بطاقة صراف الالي | BH25: بطاقة صراف الالي | BI25: =D20 -> 0 | BJ25: بطاقة صراف الالي | BM25: بطاقة صراف الالي | BO25: بطاقة صراف الالي | BQ25: بطاقة صراف الالي | BR25: =D21 -> 0 | BS25: بطاقة صراف الالي | BV25: بطاقة صراف الالي | BX25: بطاقة صراف الالي | BZ25: بطاقة صراف الالي | CA25: =D27 -> 0 | CB25: بطاقة صراف الالي | CE25: بطاقة صراف الالي | CG25: بطاقة صراف الالي | CI25: بطاقة صراف الالي | CJ25: =D67 -> 0 | CK25: بطاقة صراف الالي | CN25: بطاقة صراف الالي | CP25: بطاقة صراف الالي | CR25: بطاقة صراف الالي | CS25: =D16 -> 0 | CT25: بطاقة صراف الالي | CW25: بطاقة صراف الالي | CY25: بطاقة صراف الالي | DA25: بطاقة صراف الالي | DB25: =D28 -> 0 | DC25: بطاقة صراف الالي | DF25: بطاقة صراف الالي | DH25: بطاقة صراف الالي | DJ25: بطاقة صراف الالي | DK25: =D44 -> 0 | DL25: بطاقة صراف الالي | DO25: بطاقة صراف الالي | DQ25: بطاقة صراف الالي | DS25: بطاقة صراف الالي | DT25: =D47 -> 0 | DU25: بطاقة صراف الالي
B26: شهر 11 | G26: غير محسوب ذي الشهر | H26: دفع مشتريات بطاقة الفيزا متنوعة ٣ | I26: - | O26: BBK | P26: =AG75+AG84+AG93+AE8+AN8+AW8+BF8+BO8+BX8+AE30+AN30+AW30+BF30+AE52+AN52+AW52+BF52+BO52+BO30+BX30+BX52+CG8+CG30+CG52+CP8+CP30+CP52+CY8+CY30+CY52+DH8+DH30+DH52+DQ8+DQ30 -> 0 | AC26: غير محسوب ذي الشهر | AE26: غير محسوب ذي الشهر | AG26: غير محسوب ذي الشهر | AI26: غير محسوب ذي الشهر | AJ26: =D23 -> 0 | AL26: غير محسوب ذي الشهر | AN26: غير محسوب ذي الشهر | AP26: غير محسوب ذي الشهر | AR26: غير محسوب ذي الشهر | AS26: =D18 -> 0 | AU26: غير محسوب ذي الشهر | AW26: غير محسوب ذي الشهر | AY26: غير محسوب ذي الشهر | BA26: غير محسوب ذي الشهر | BB26: =D19 -> 0 | BD26: غير محسوب ذي الشهر | BF26: غير محسوب ذي الشهر | BH26: غير محسوب ذي الشهر | BJ26: غير محسوب ذي الشهر | BK26: =D20 -> 0 | BM26: غير محسوب ذي الشهر | BO26: غير محسوب ذي الشهر | BQ26: غير محسوب ذي الشهر | BS26: غير محسوب ذي الشهر | BT26: =D21 -> 0 | BV26: غير محسوب ذي الشهر | BX26: غير محسوب ذي الشهر | BZ26: غير محسوب ذي الشهر | CB26: غير محسوب ذي الشهر | CC26: =D27 -> 0 | CE26: غير محسوب ذي الشهر | CG26: غير محسوب ذي الشهر | CI26: غير محسوب ذي الشهر | CK26: غير محسوب ذي الشهر | CL26: =D67 -> 0 | CN26: غير محسوب ذي الشهر | CP26: غير محسوب ذي الشهر | CR26: غير محسوب ذي الشهر | CT26: غير محسوب ذي الشهر | CU26: =D16 -> 0 | CW26: غير محسوب ذي الشهر | CY26: غير محسوب ذي الشهر | DA26: غير محسوب ذي الشهر | DC26: غير محسوب ذي الشهر | DD26: =D28 -> 0 | DF26: غير محسوب ذي الشهر | DH26: غير محسوب ذي الشهر | DJ26: غير محسوب ذي الشهر | DL26: غير محسوب ذي الشهر | DM26: =D44 -> 0 | DO26: غير محسوب ذي الشهر | DQ26: غير محسوب ذي الشهر | DS26: غير محسوب ذي الشهر | DU26: غير محسوب ذي الشهر | DV26: =D47 -> 0
B27: شهر 12 | G27: بطاقة صراف الالي | H27: بترول جميع السيارات | I27: - | O27: MEEM | P27: =AI75+AI84+AI93+AE19+AN19+AW19+BF19+BO19+BX19+AE41+AN41+AW41+BF41+AE63+AN63+AW63+BF63+BO63+BO41+BX41+BX63+CG19+CG41+CG63+CP19+CP41+CP63+CY19+CY41+CY63+DH19+DH41+DH63+DQ19+DQ41 -> 0
B28: سلف و دين واقساط | G28: بطاقة صراف الالي | H28: عامل التنظيف لجميع السيارات | I28: - | O28: NBB | P28: =AK75+AK84+AK93+AG8+AP8+AY8+BH8+BQ8+BZ8+AG30+AP30+AY30+BH30+AG52+AP52+AY52+BH52+BQ52+BQ30+BZ30+BZ52+CI8+CI30+CI52+CR8+CR30+CR52+DA8+DA30+DA52+DJ8+DJ30+DJ52+DS8+DS30 -> 0
G29: بطاقة صراف الالي | H29: تصليح السيارة ( تبديل قطع غيار , صباغة و غيره) | I29: - | O29: بطاقة صراف الالي | P29: =AG19+AP19+AY19+BH19+BQ19+BZ19+AG41+AP41+AY41+AG63+AP63+AY63+BH63+BQ63+BQ41+BZ41+BZ63+BH41+CI19+CI41+CI63+CR19+CR41+CR63+DA19+DA41+DA63+DJ19+DJ41+DJ63+DS19+DS41 -> 0 | AC29: تصليح سيارة ١٫١ | AE29: تصليح سيارة ١٫٣ | AG29: تصليح سيارة ١٫٥ | AL29: تصليح سيارة 2.1 | AN29: تصليح سيارة 2.3 | AP29: تصليح سيارة 2.5 | AU29: تعديل البيت ١٫١ | AW29: تعديل البيت ١٫٣ | AY29: تعديل البيت ١٫٥ | BD29: تعديل البيت ٢٫١ | BF29: تعديل البيت ٢٫٣ | BH29: تعديل البيت ٢٫٥ | BM29: دروس تقوية للأطفال و الكبار 1.1 | BO29: دروس تقوية للأطفال و الكبار 1.3 | BQ29: دروس تقوية للأطفال و الكبار 1.5 | BV29: احتياجات ألاطفال 1.1 | BX29: احتياجات ألاطفال 1.3 | BZ29: احتياجات ألاطفال 1.5 | CE29: قسط البنك 1.1 | CG29: قسط البنك 1.3 | CI29: قسط البنك 1.5 | CN29: مصروف العائلة 1.1 | CP29: مصروف العائلة 1.3 | CR29: مصروف العائلة 1.5 | CW29: ادخار للحج 1.1 | CY29: ادخار للحج 1.3 | DA29: ادخار للحج 1.5 | DF29: استثمار 1.1 | DH29: استثمار 1.3 | DJ29: استثمار 1.5 | DO29: ادخار للسفر 1.1 | DQ29: ادخار للسفر 1.3 | DS29: ادخار للسفر 1.5
G30: بطاقة صراف الالي | I30: - | O30: غير محسوب ذي الشهر | P30: =AM93+AM84+AM75+AI19+AI41+AI63+AR19+AR41+AR63+BA19+BA41+BA63+BJ19+BJ41+BJ63+BS63+BS41+BS19+CB19+CB41+CB63+CK19+CK41+CK63+CT19+CT41+CT63+DC19+DC41+DC63+DL19+DL41+DL63+DU19+DU41 -> 0 | AC30: =VLOOKUP(G29,AC31:AD37,2,FALSE) -> 0 | AE30: =VLOOKUP(G29,AE31:AF37,2,FALSE) -> 0 | AG30: =VLOOKUP(G29,AG31:AH37,2,FALSE) -> 0 | AL30: =VLOOKUP(G30,AL31:AM37,2,FALSE) -> 0 | AN30: =VLOOKUP(G30,AN31:AO37,2,FALSE) -> 0 | AP30: =VLOOKUP(G30,AP31:AQ37,2,FALSE) -> 0 | AU30: =VLOOKUP(G31,AU31:AV37,2,FALSE) -> 0 | AW30: =VLOOKUP(G31,AW31:AX37,2,FALSE) -> 0 | AY30: =VLOOKUP(G31,AY31:AZ37,2,FALSE) -> 0 | BD30: =VLOOKUP(G32,BD31:BE37,2,FALSE) -> 0 | BF30: =VLOOKUP(G32,BF31:BG37,2,FALSE) -> 0 | BH30: =VLOOKUP(G32,BH31:BI37,2,FALSE) -> 0 | BM30: =VLOOKUP(G39,BM31:BN37,2,FALSE) -> 0 | BO30: =VLOOKUP(G39,BO31:BP37,2,FALSE) -> 0 | BQ30: =VLOOKUP(G39,BQ31:BR37,2,FALSE) -> 0 | BV30: =VLOOKUP(G40,BV31:BW37,2,FALSE) -> 0 | BX30: =VLOOKUP(G40,BX31:BY37,2,FALSE) -> 0 | BZ30: =VLOOKUP(G40,BZ31:CA37,2,FALSE) -> 0 | CE30: =VLOOKUP(H74,CE31:CF37,2,FALSE) -> 0 | CG30: =VLOOKUP(H74,CG31:CH37,2,FALSE) -> 0 | CI30: =VLOOKUP(H74,CI31:CJ37,2,FALSE) -> 0 | CN30: =VLOOKUP(G17,CN31:CO37,2,FALSE) -> 0 | CP30: =VLOOKUP(G17,CP31:CQ37,2,FALSE) -> 0 | CR30: =VLOOKUP(G17,CR31:CS37,2,FALSE) -> 0 | CW30: =VLOOKUP(G42,CW31:CX37,2,FALSE) -> 0 | CY30: =VLOOKUP(G42,CY31:CZ37,2,FALSE) -> 0 | DA30: =VLOOKUP(G42,DA31:DB37,2,FALSE) -> 0 | DF30: =VLOOKUP(G45,DF31:DG37,2,FALSE) -> 0 | DH30: =VLOOKUP(G45,DH31:DI37,2,FALSE) -> 0 | DJ30: =VLOOKUP(G45,DJ31:DK37,2,FALSE) -> 0 | DO30: =VLOOKUP(G48,DO31:DP37,2,FALSE) -> 0 | DQ30: =VLOOKUP(G48,DQ31:DR37,2,FALSE) -> 0 | DS30: =VLOOKUP(G48,DS31:DT37,2,FALSE) -> 0
G31: بطاقة صراف الالي | H31: تعديل او تصليح او ( إضافة في المنزل مثل شراء أغراض ) | I31: - | AC31: NBK | AD31: =D29 -> 0 | AE31: NBK | AG31: NBK | AL31: NBK | AM31: =D30 -> 0 | AN31: NBK | AP31: NBK | AU31: NBK | AV31: =D31 -> 0 | AW31: NBK | AY31: NBK | BD31: NBK | BE31: =D32 -> 0 | BF31: NBK | BH31: NBK | BM31: NBK | BN31: =D39 -> 0 | BO31: NBK | BQ31: NBK | BV31: NBK | BW31: =D41+E41+F41 -> 0 | BX31: NBK | BZ31: NBK | CE31: NBK | CF31: =D73 -> 0 | CG31: NBK | CI31: NBK | CN31: NBK | CO31: =D17 -> 0 | CP31: NBK | CR31: NBK | CW31: NBK | CX31: =D42 -> 0 | CY31: NBK | DA31: NBK | DF31: NBK | DG31: =D45 -> 0 | DH31: NBK | DJ31: NBK | DO31: NBK | DP31: =D48 -> 0 | DQ31: NBK | DS31: NBK
G32: بطاقة صراف الالي | I32: - | AC32: ILA | AE32: ILA | AG32: ILA | AL32: ILA | AN32: ILA | AP32: ILA | AU32: ILA | AW32: ILA | AY32: ILA | BD32: ILA | BF32: ILA | BH32: ILA | BM32: ILA | BO32: ILA | BQ32: ILA | BV32: ILA | BX32: ILA | BZ32: ILA | CE32: ILA | CG32: ILA | CI32: ILA | CN32: ILA | CP32: ILA | CR32: ILA | CW32: ILA | CY32: ILA | DA32: ILA | DF32: ILA | DH32: ILA | DJ32: ILA | DO32: ILA | DQ32: ILA | DS32: ILA
G33: - | H33: تكاليف العيدميلاد | AC33: BBK | AE33: BBK | AF33: =D29 -> 0 | AG33: BBK | AL33: BBK | AN33: BBK | AO33: =D30 -> 0 | AP33: BBK | AU33: BBK | AW33: BBK | AX33: =D31 -> 0 | AY33: BBK | BD33: BBK | BF33: BBK | BG33: =D32 -> 0 | BH33: BBK | BM33: BBK | BO33: BBK | BP33: =D39 -> 0 | BQ33: BBK | BV33: BBK | BX33: BBK | BY33: =D41+E41+F41 -> 0 | BZ33: BBK | CE33: BBK | CG33: BBK | CH33: =D73 -> 0 | CI33: BBK | CN33: BBK | CP33: BBK | CQ33: =D17 -> 0 | CR33: BBK | CW33: BBK | CY33: BBK | CZ33: =D42 -> 0 | DA33: BBK | DF33: BBK | DH33: BBK | DI33: =D45 -> 0 | DJ33: BBK | DO33: BBK | DQ33: BBK | DR33: =D48 -> 0 | DS33: BBK
G34: بطاقة صراف الالي | I34: - | O34: بطاقة الفيزاء مجرد معلومات عامة ( غير محسوب في الجدول ) | AC34: MEEM | AE34: MEEM | AG34: MEEM | AL34: MEEM | AN34: MEEM | AP34: MEEM | AU34: MEEM | AW34: MEEM | AY34: MEEM | BD34: MEEM | BF34: MEEM | BH34: MEEM | BM34: MEEM | BO34: MEEM | BQ34: MEEM | BV34: MEEM | BX34: MEEM | BZ34: MEEM | CE34: MEEM | CG34: MEEM | CI34: MEEM | CN34: MEEM | CP34: MEEM | CR34: MEEM | CW34: MEEM | CY34: MEEM | DA34: MEEM | DF34: MEEM | DH34: MEEM | DJ34: MEEM | DO34: MEEM | DQ34: MEEM | DS34: MEEM
G35: بطاقة صراف الالي | H35: مدرسة خاصة | I35: - | P35: الي لازم ادفع | AC35: NBB | AE35: NBB | AG35: NBB | AH35: =D29 -> 0 | AL35: NBB | AN35: NBB | AP35: NBB | AQ35: =D30 -> 0 | AU35: NBB | AW35: NBB | AY35: NBB | AZ35: =D31 -> 0 | BD35: NBB | BF35: NBB | BH35: NBB | BI35: =D32 -> 0 | BM35: NBB | BO35: NBB | BQ35: NBB | BR35: =D39 -> 0 | BV35: NBB | BX35: NBB | BZ35: NBB | CA35: =D41+E41+F41 -> 0 | CE35: NBB | CG35: NBB | CI35: NBB | CJ35: =D73 -> 0 | CN35: NBB | CP35: NBB | CR35: NBB | CS35: =D17 -> 0 | CW35: NBB | CY35: NBB | DA35: NBB | DB35: =D42 -> 0 | DF35: NBB | DH35: NBB | DJ35: NBB | DK35: =D45 -> 0 | DO35: NBB | DQ35: NBB | DS35: NBB | DT35: =D48 -> 0
G36: بطاقة صراف الالي | H36: روضة | I36: - | P36: تامين مالي + تسجيل سيارة | AC36: بطاقة صراف الالي | AE36: بطاقة صراف الالي | AG36: بطاقة صراف الالي | AL36: بطاقة صراف الالي | AN36: بطاقة صراف الالي | AP36: بطاقة صراف الالي | AU36: بطاقة صراف الالي | AW36: بطاقة صراف الالي | AY36: بطاقة صراف الالي | BD36: بطاقة صراف الالي | BF36: بطاقة صراف الالي | BH36: بطاقة صراف الالي | BM36: بطاقة صراف الالي | BO36: بطاقة صراف الالي | BQ36: بطاقة صراف الالي | BV36: بطاقة صراف الالي | BX36: بطاقة صراف الالي | BZ36: بطاقة صراف الالي | CE36: بطاقة صراف الالي | CG36: بطاقة صراف الالي | CI36: بطاقة صراف الالي | CN36: بطاقة صراف الالي | CP36: بطاقة صراف الالي | CR36: بطاقة صراف الالي | CW36: بطاقة صراف الالي | CY36: بطاقة صراف الالي | DA36: بطاقة صراف الالي | DF36: بطاقة صراف الالي | DH36: بطاقة صراف الالي | DJ36: بطاقة صراف الالي | DO36: بطاقة صراف الالي | DQ36: بطاقة صراف الالي | DS36: بطاقة صراف الالي
G37: بطاقة صراف الالي | H37: جامعة | I37: - | P37: تامين + تسجيل سيارة ابوي | AC37: غير محسوب ذي الشهر | AE37: غير محسوب ذي الشهر | AG37: غير محسوب ذي الشهر | AL37: غير محسوب ذي الشهر | AN37: غير محسوب ذي الشهر | AP37: غير محسوب ذي الشهر | AU37: غير محسوب ذي الشهر | AW37: غير محسوب ذي الشهر | AY37: غير محسوب ذي الشهر | BD37: غير محسوب ذي الشهر | BF37: غير محسوب ذي الشهر | BH37: غير محسوب ذي الشهر | BM37: غير محسوب ذي الشهر | BO37: غير محسوب ذي الشهر | BQ37: غير محسوب ذي الشهر | BV37: غير محسوب ذي الشهر | BX37: غير محسوب ذي الشهر | BZ37: غير محسوب ذي الشهر | CE37: غير محسوب ذي الشهر | CG37: غير محسوب ذي الشهر | CI37: غير محسوب ذي الشهر | CN37: غير محسوب ذي الشهر | CP37: غير محسوب ذي الشهر | CR37: غير محسوب ذي الشهر | CW37: غير محسوب ذي الشهر | CY37: غير محسوب ذي الشهر | DA37: غير محسوب ذي الشهر | DF37: غير محسوب ذي الشهر | DH37: غير محسوب ذي الشهر | DJ37: غير محسوب ذي الشهر | DO37: غير محسوب ذي الشهر | DQ37: غير محسوب ذي الشهر | DS37: غير محسوب ذي الشهر
G38: بطاقة صراف الالي | H38: مواصلات المدرسة او الجامعة | I38: - | P38: كهرباء
G39: بطاقة صراف الالي | H39: دروس تقوية للأطفال و الكبار | I39: - | P39: بيل تلفوني + الفايبر
D40: العيد | E40: الملابس | F40: المدرسة | G40: بطاقة صراف الالي | H40: احتياجات ألاطفال | I40: - | P40: تصليح سيارتي | AC40: تصليح سيارة ١٫٢ | AE40: تصليح سيارة ١٫٤ | AG40: تصليح سيارة ١٫٦ | AI40: تصليح سيارة ١٫٧ | AL40: تصليح سيارة 2.2 | AN40: تصليح سيارة 2.4 | AP40: تصليح سيارة 2.6 | AR40: تصليح سيارة 2.7 | AU40: تعديل البيت ١٫٢ | AW40: تعديل البيت ١٫٤ | AY40: تعديل البيت ١٫٦ | BA40: تعديل البيت ١٫٧ | BD40: تعديل البيت ٢٫٢ | BF40: تعديل البيت ٢٫٤ | BH40: تعديل البيت ٢٫٦ | BJ40: تعديل البيت ٢٫٧ | BM40: دروس تقوية للأطفال و الكبار 1.2 | BO40: دروس تقوية للأطفال و الكبار 1.4 | BQ40: دروس تقوية للأطفال و الكبار 1.6 | BS40: دروس تقوية للأطفال و الكبار 1.7 | BV40: احتياجات ألاطفال 1.2 | BX40: احتياجات ألاطفال 1.4 | BZ40: احتياجات ألاطفال 1.6 | CB40: احتياجات ألاطفال 1.7 | CE40: قسط البنك 1.2 | CG40: قسط البنك 1.4 | CI40: قسط البنك 1.6 | CK40: قسط البنك 1.7 | CN40: مصروف العائلة 1.2 | CP40: مصروف العائلة 1.4 | CR40: مصروف العائلة 1.6 | CT40: مصروف العائلة 1.7 | CW40: ادخار للحج 1.2 | CY40: ادخار للحج 1.4 | DA40: ادخار للحج 1.6 | DC40: ادخار للحج 1.7 | DF40: استثمار 1.2 | DH40: استثمار 1.4 | DJ40: استثمار 1.6 | DL40: استثمار 1.7 | DO40: ادخار للسفر 1.2 | DQ40: ادخار للسفر 1.4 | DS40: ادخار للسفر 1.6 | DU40: ادخار للسفر 1.7
P41: تصليح أي شي كهربائي فالمنزل | AC41: =VLOOKUP(G29,AC42:AD48,2,FALSE) -> 0 | AE41: =VLOOKUP(G29,AE42:AF48,2,FALSE) -> 0 | AG41: =VLOOKUP(G29,AG42:AH48,2,FALSE) -> 0 | AI41: =VLOOKUP(G29,AI42:AJ48,2,FALSE) -> 0 | AL41: =VLOOKUP(G30,AL42:AM48,2,FALSE) -> 0 | AN41: =VLOOKUP(G30,AN42:AO48,2,FALSE) -> 0 | AP41: =VLOOKUP(G30,AP42:AQ48,2,FALSE) -> 0 | AR41: =VLOOKUP(G30,AR42:AS48,2,FALSE) -> 0 | AU41: =VLOOKUP(G31,AU42:AV48,2,FALSE) -> 0 | AW41: =VLOOKUP(G31,AW42:AX48,2,FALSE) -> 0 | AY41: =VLOOKUP(G31,AY42:AZ48,2,FALSE) -> 0 | BA41: =VLOOKUP(G31,BA42:BB48,2,FALSE) -> 0 | BD41: =VLOOKUP(G32,BD42:BE48,2,FALSE) -> 0 | BF41: =VLOOKUP(G32,BF42:BG48,2,FALSE) -> 0 | BH41: =VLOOKUP(G32,BH42:BI48,2,FALSE) -> 0 | BJ41: =VLOOKUP(G32,BJ42:BK48,2,FALSE) -> 0 | BM41: =VLOOKUP(G39,BM42:BN48,2,FALSE) -> 0 | BO41: =VLOOKUP(G39,BO42:BP48,2,FALSE) -> 0 | BQ41: =VLOOKUP(G39,BQ42:BR48,2,FALSE) -> 0 | BS41: =VLOOKUP(G39,BS42:BT48,2,FALSE) -> 0 | BV41: =VLOOKUP(G40,BV42:BW48,2,FALSE) -> 0 | BX41: =VLOOKUP(G40,BX42:BY48,2,FALSE) -> 0 | BZ41: =VLOOKUP(G40,BZ42:CA48,2,FALSE) -> 0 | CB41: =VLOOKUP(G40,CB42:CC48,2,FALSE) -> 0 | CE41: =VLOOKUP(H74,CE42:CF48,2,FALSE) -> 0 | CG41: =VLOOKUP(H74,CG42:CH48,2,FALSE) -> 0 | CI41: =VLOOKUP(H74,CI42:CJ48,2,FALSE) -> 0 | CK41: =VLOOKUP(H74,CK42:CL48,2,FALSE) -> 0 | CN41: =VLOOKUP(G17,CN42:CO48,2,FALSE) -> 0 | CP41: =VLOOKUP(G17,CP42:CQ48,2,FALSE) -> 0 | CR41: =VLOOKUP(G17,CR42:CS48,2,FALSE) -> 0 | CT41: =VLOOKUP(G17,CT42:CU48,2,FALSE) -> 0 | CW41: =VLOOKUP(G42,CW42:CX48,2,FALSE) -> 0 | CY41: =VLOOKUP(G42,CY42:CZ48,2,FALSE) -> 0 | DA41: =VLOOKUP(G42,DA42:DB48,2,FALSE) -> 0 | DC41: =VLOOKUP(G42,DC42:DD48,2,FALSE) -> 0 | DF41: =VLOOKUP(G45,DF42:DG48,2,FALSE) -> 0 | DH41: =VLOOKUP(G45,DH42:DI48,2,FALSE) -> 0 | DJ41: =VLOOKUP(G45,DJ42:DK48,2,FALSE) -> 0 | DL41: =VLOOKUP(G45,DL42:DM48,2,FALSE) -> 0 | DO41: =VLOOKUP(G48,DO42:DP48,2,FALSE) -> 0 | DQ41: =VLOOKUP(G48,DQ42:DR48,2,FALSE) -> 0 | DS41: =VLOOKUP(G48,DS42:DT48,2,FALSE) -> 0 | DU41: =VLOOKUP(G48,DU42:DV48,2,FALSE) -> 0
G42: بطاقة صراف الالي | H42: ادخار للحج | I42: - | P42: تصليح أي شي الكتروني فالمنزل | AC42: NBK | AE42: NBK | AG42: NBK | AI42: NBK | AL42: NBK | AN42: NBK | AP42: NBK | AR42: NBK | AU42: NBK | AW42: NBK | AY42: NBK | BA42: NBK | BD42: NBK | BF42: NBK | BH42: NBK | BJ42: NBK | BM42: NBK | BO42: NBK | BQ42: NBK | BS42: NBK | BV42: NBK | BX42: NBK | BZ42: NBK | CB42: NBK | CE42: NBK | CG42: NBK | CI42: NBK | CK42: NBK | CN42: NBK | CP42: NBK | CR42: NBK | CT42: NBK | CW42: NBK | CY42: NBK | DA42: NBK | DC42: NBK | DF42: NBK | DH42: NBK | DJ42: NBK | DL42: NBK | DO42: NBK | DQ42: NBK | DS42: NBK | DU42: NBK
...

Sheet 2
G2: اخر تحديث بتاريخ | S2: بدون اقتطاع ادخار + الحج
D4: جدول شهر 2 | N4: النسبة المئوية للراتب الشهري فقط | S4: النسبة المئوية للراتب الشهري فقط
N5: الاستثمار | O5: ادخار الحج | P5: ادخار ( تأمين و تسجيل + ثياب العيد ) + للسفر | Q5: مصاريف متنوعة | S5: الاستثمار | U5: مصاريف متنوعة
B6: اضغط هنا للرجوع الى الصفحة الرئيسية | G6: راتب الشهري | I6: * | N6: =(DF30+DH30+DJ30+DF41+DH41+DJ41)/(D6+U83+AA83+AA89+U89)*1 -> #DIV/0! | O6: =(CW30+CY30+DA30+CW41+CY41+DA41)/(D6+U83+AA83+AA89+U89)*1 -> #DIV/0! | P6: =(DO30+DQ30+DS30+DO41+DQ41+DS41+DO8+DQ8+DS8+DO19+DQ19+DS19)/(D6+U83+AA83+AA89+U89)*1 -> #DIV/0! | Q6: =(D103-N7)/(D6+U83+AA83+AA89+U89)*1 -> #DIV/0! | S6: =(DF30+DH30+DJ30+DF41+DH41+DJ41)/(D6+U83+AA83+AA89+U89)*1 -> #DIV/0! | U6: =(D103-N7)/(D6+U83+AA83+AA89+U89)*1 -> #DIV/0!
N7: =DF30+DH30+DJ30+DF41+DH41+DJ41 -> 0 | O7: =CW30+CY30+DA30+CW41+CY41+DA41 -> 0 | P7: =DO30+DQ30+DS30+DO41+DQ41+DS41+DO8+DQ8+DS8+DO19+DQ19+DS19 -> 0 | Q7: =(D6+U83+AA83+AA89+U89)*Q6/1 -> #DIV/0! | S7: =DF30+DH30+DJ30+DF41+DH41+DJ41 -> 0 | U7: =(D6+U83+AA83+AA89+U89)*Q6/1 -> #DIV/0! | AC7: علاج 1 | AE7: علاج 3 | AG7: علاج 5 | AL7: اجار الشقة ١٫١ | AN7: اجار الشقة ١٫٣ | AP7: اجار الشقة ١٫٥ | AU7: ماجلة البيت ١٫١ | AW7: ماجلة البيت ١٫٣ | AY7: ماجلة البيت ١٫٥ | BD7: جميع الابيال ١٫١ | BF7: جميع الابيال ١٫٣ | BH7: جميع الابيال ١٫٥ | BM7: بيل الكهرباء ١٫١ | BO7: بيل الكهرباء ١٫٣ | BQ7: بيل الكهرباء ١٫٥ | BV7: بترول الجميع ١٫١ | BX7: بترول الجميع ١٫٣ | BZ7: بترول الجميع ١٫٥ | CE7: قسط بطاقة الفيزا البنكية 1.1 | CG7: قسط بطاقة الفيزا البنكية 1.3 | CI7: قسط بطاقة الفيزا البنكية 1.5 | CN7: راتب الزوجة 1.1 | CP7: راتب الزوجة 1.3 | CR7: راتب الزوجة 1.5 | CW7: عامل التنظيف لجميع السيارات 1.1 | CY7: عامل التنظيف لجميع السيارات 1.3 | DA7: عامل التنظيف لجميع السيارات 1.5 | DF7: جمعية 1.1 | DH7: جمعية 1.3 | DJ7: جمعية 1.5 | DO7: ادخار ( تأمين و تسجيل + ثياب العيد + الروضة ) 1.1 | DQ7: ادخار ( تأمين و تسجيل + ثياب العيد + الروضة ) 1.3 | DS7: ادخار ( تأمين و تسجيل + ثياب العيد + الروضة ) 1.5
D8: دخل ايضافي كل شهر | N8: =(Q6+O6+N6+P6) -> #DIV/0! | P8: مجموع النسبة المئوية الكلي | S8: =(U6+S6) -> #DIV/0! | U8: مجموع النسبة المئوية الكلي | AC8: =VLOOKUP(G23,AC9:AD15,2,FALSE) -> 0 | AE8: =VLOOKUP(G23,AE9:AF15,2,FALSE) -> 0 | AG8: =VLOOKUP(G23,AG9:AH15,2,FALSE) -> 0 | AL8: =VLOOKUP(G18,AL9:AM15,2,FALSE) -> 0 | AN8: =VLOOKUP(G18,AN9:AO15,2,FALSE) -> 0 | AP8: =VLOOKUP(G18,AP9:AQ15,2,FALSE) -> 0 | AU8: =VLOOKUP(G19,AU9:AV15,2,FALSE) -> 0 | AW8: =VLOOKUP(G19,AW9:AX15,2,FALSE) -> 0 | AY8: =VLOOKUP(G19,AY9:AZ15,2,FALSE) -> 0 | BD8: =VLOOKUP(G20,BD9:BE15,2,FALSE) -> 0 | BF8: =VLOOKUP(G20,BF9:BG15,2,FALSE) -> 0 | BH8: =VLOOKUP(G20,BH9:BI15,2,FALSE) -> 0 | BM8: =VLOOKUP(G21,BM9:BN15,2,FALSE) -> 0 | BO8: =VLOOKUP(G21,BO9:BP15,2,FALSE) -> 0 | BQ8: =VLOOKUP(G21,BQ9:BR15,2,FALSE) -> 0 | BV8: =VLOOKUP(G27,BV9:BW15,2,FALSE) -> 0 | BX8: =VLOOKUP(G27,BX9:BY15,2,FALSE) -> 0 | BZ8: =VLOOKUP(G27,BZ9:CA15,2,FALSE) -> 0 | CE8: =VLOOKUP(H68,CE9:CF15,2,FALSE) -> 0 | CG8: =VLOOKUP(H68,CG9:CH15,2,FALSE) -> 0 | CI8: =VLOOKUP(H68,CI9:CJ15,2,FALSE) -> 0 | CN8: =VLOOKUP(G16,CN9:CO15,2,FALSE) -> 0 | CP8: =VLOOKUP(G16,CP9:CQ15,2,FALSE) -> 0 | CR8: =VLOOKUP(G16,CR9:CS15,2,FALSE) -> 0 | CW8: =VLOOKUP(G28,CW9:CX15,2,FALSE) -> 0 | CY8: =VLOOKUP(G28,CY9:CZ15,2,FALSE) -> 0 | DA8: =VLOOKUP(G28,DA9:DB15,2,FALSE) -> 0 | DF8: =VLOOKUP(G44,DF9:DG15,2,FALSE) -> 0 | DH8: =VLOOKUP(G44,DH9:DI15,2,FALSE) -> 0 | DJ8: =VLOOKUP(G44,DJ9:DK15,2,FALSE) -> 0 | DO8: =VLOOKUP(G47,DO9:DP15,2,FALSE) -> 0 | DQ8: =VLOOKUP(G47,DQ9:DR15,2,FALSE) -> 0 | DS8: =VLOOKUP(G47,DS9:DT15,2,FALSE) -> 0
G9: غلاء المعيشة | I9: * | N9: =N7+Q7+O7+P7 -> #DIV/0! | S9: =S7+U7 -> #DIV/0! | AC9: NBK | AD9: =D23 -> 0 | AE9: NBK | AG9: NBK | AL9: NBK | AM9: =D18 -> 0 | AN9: NBK | AP9: NBK | AU9: NBK | AV9: =D19 -> 0 | AW9: NBK | AY9: NBK | BD9: NBK | BE9: =D20 -> 0 | BF9: NBK | BH9: NBK | BM9: NBK | BN9: =D21 -> 0 | BO9: NBK | BQ9: NBK | BV9: NBK | BW9: =D27 -> 0 | BX9: NBK | BZ9: NBK | CE9: NBK | CF9: =D67 -> 0 | CG9: NBK | CI9: NBK | CN9: NBK | CO9: =D16 -> 0 | CP9: NBK | CR9: NBK | CW9: NBK | CX9: =D28 -> 0 | CY9: NBK | DA9: NBK | DF9: NBK | DG9: =D44 -> 0 | DH9: NBK | DJ9: NBK | DO9: NBK | DP9: =D47 -> 0 | DQ9: NBK | DS9: NBK
G10: علاوة إسكان | I10: * | N10: =1-N8 -> #DIV/0! | P10: المتبقي من الراتب | S10: =1-S8 -> #DIV/0! | U10: المتبقي من الراتب | AC10: ILA | AE10: ILA | AG10: ILA | AL10: ILA | AN10: ILA | AP10: ILA | AU10: ILA | AW10: ILA | AY10: ILA | BD10: ILA | BF10: ILA | BH10: ILA | BM10: ILA | BO10: ILA | BQ10: ILA | BV10: ILA | BX10: ILA | BZ10: ILA | CE10: ILA | CG10: ILA | CI10: ILA | CN10: ILA | CP10: ILA | CR10: ILA | CW10: ILA | CY10: ILA | DA10: ILA | DF10: ILA | DH10: ILA | DJ10: ILA | DO10: ILA | DQ10: ILA | DS10: ILA
G11: لا مـــــا بتــــــــنزل ذي الشهر | H11: دعم اللحوم كل ثلاث شهور | I11: * | N11: =((D6+U83+AA83+AA89+U89)*N10)/1 -> #DIV/0! | S11: =((D6+U83+AA83+AA89+U89)*S10)/1 -> #DIV/0! | AC11: BBK | AE11: BBK | AF11: =D23 -> 0 | AG11: BBK | AL11: BBK | AN11: BBK | AO11: =D18 -> 0 | AP11: BBK | AU11: BBK | AW11: BBK | AX11: =D19 -> 0 | AY11: BBK | BD11: BBK | BF11: BBK | BG11: =D20 -> 0 | BH11: BBK | BM11: BBK | BO11: BBK | BP11: =D21 -> 0 | BQ11: BBK | BV11: BBK | BX11: BBK | BY11: =D27 -> 0 | BZ11: BBK | CE11: BBK | CG11: BBK | CH11: =D67 -> 0 | CI11: BBK | CN11: BBK | CP11: BBK | CQ11: =D16 -> 0 | CR11: BBK | CW11: BBK | CY11: BBK | CZ11: =D28 -> 0 | DA11: BBK | DF11: BBK | DH11: BBK | DI11: =D44 -> 0 | DJ11: BBK | DO11: BBK | DQ11: BBK | DR11: =D47 -> 0 | DS11: BBK
G12: مساعدات خيرية | I12: * | AC12: MEEM | AE12: MEEM | AG12: MEEM | AL12: MEEM | AN12: MEEM | AP12: MEEM | AU12: MEEM | AW12: MEEM | AY12: MEEM | BD12: MEEM | BF12: MEEM | BH12: MEEM | BM12: MEEM | BO12: MEEM | BQ12: MEEM | BV12: MEEM | BX12: MEEM | BZ12: MEEM | CE12: MEEM | CG12: MEEM | CI12: MEEM | CN12: MEEM | CP12: MEEM | CR12: MEEM | CW12: MEEM | CY12: MEEM | DA12: MEEM | DF12: MEEM | DH12: MEEM | DJ12: MEEM | DO12: MEEM | DQ12: MEEM | DS12: MEEM
G13: مدخول اعمال حرة او خاص او جمعية او غيرها | I13: * | N13: النسبة المئوية للراتب الشهري + المدخول الإضافي | S13: النسبة المئوية للراتب الشهري + المدخول الإضافي | AC13: NBB | AE13: NBB | AG13: NBB | AH13: =D23 -> 0 | AL13: NBB | AN13: NBB | AP13: NBB | AQ13: =D18 -> 0 | AU13: NBB | AW13: NBB | AY13: NBB | AZ13: =D19 -> 0 | BD13: NBB | BF13: NBB | BH13: NBB | BI13: =D20 -> 0 | BM13: NBB | BO13: NBB | BQ13: NBB | BR13: =D21 -> 0 | BV13: NBB | BX13: NBB | BZ13: NBB | CA13: =D27 -> 0 | CE13: NBB | CG13: NBB | CI13: NBB | CJ13: =D67 -> 0 | CN13: NBB | CP13: NBB | CR13: NBB | CS13: =D16 -> 0 | CW13: NBB | CY13: NBB | DA13: NBB | DB13: =D28 -> 0 | DF13: NBB | DH13: NBB | DJ13: NBB | DK13: =D44 -> 0 | DO13: NBB | DQ13: NBB | DS13: NBB | DT13: =D47 -> 0
E14: لا | G14: ركز اهني هل يوجد عيد في ذي الشهر حق لثياب او العيادي | I14: مجرد ملاحظة و مارح ينحسب , اختار البنك | K14: مــــــــــــــلاحظات | N14: الاستثمار | O14: ادخار الحج | P14: ادخار ( تأمين و تسجيل + ثياب العيد ) + للسفر | Q14: مصاريف متنوع | S14: الاستثمار | U14: مصاريف متنوع | AC14: بطاقة صراف الالي | AE14: بطاقة صراف الالي | AG14: بطاقة صراف الالي | AL14: بطاقة صراف الالي | AN14: بطاقة صراف الالي | AP14: بطاقة صراف الالي | AU14: بطاقة صراف الالي | AW14: بطاقة صراف الالي | AY14: بطاقة صراف الالي | BD14: بطاقة صراف الالي | BF14: بطاقة صراف الالي | BH14: بطاقة صراف الالي | BM14: بطاقة صراف الالي | BO14: بطاقة صراف الالي | BQ14: بطاقة صراف الالي | BV14: بطاقة صراف الالي | BX14: بطاقة صراف الالي | BZ14: بطاقة صراف الالي | CE14: بطاقة صراف الالي | CG14: بطاقة صراف الالي | CI14: بطاقة صراف الالي | CN14: بطاقة صراف الالي | CP14: بطاقة صراف الالي | CR14: بطاقة صراف الالي | CW14: بطاقة صراف الالي | CY14: بطاقة صراف الالي | DA14: بطاقة صراف الالي | DF14: بطاقة صراف الالي | DH14: بطاقة صراف الالي | DJ14: بطاقة صراف الالي | DO14: بطاقة صراف الالي | DQ14: بطاقة صراف الالي | DS14: بطاقة صراف الالي
B15: ذهاب الى | D15: المصاريف الشهرية وتوزيعها | N15: =(DF30+DH30+DJ30+DF41+DH41+DJ41)/(D6+D9+D10+D11+D12+D13+U83+AA83+AA89+U89)*1 -> #DIV/0! | O15: =(CW30+CY30+DA30+CW41+CY41+DA41)/(D6+D9+D10+D11+D12+D13+U83+AA83+AA89+U89)*1 -> #DIV/0! | P15: =(DO30+DQ30+DS30+DO41+DQ41+DS41+DO8+DQ8+DS8+DO19+DQ19+DS19)/(D6+D9+D10+D11+D12+D13+U83+AA83+AA89+U89)*1 -> #DIV/0! | Q15: =(D103-N7)/(D6+D9+D10+D11+D12+D13+U83+AA83+AA89+U89)*1 -> #DIV/0! | S15: =(DF30+DH30+DJ30+DF41+DH41+DJ41)/(D6+D9+D10+D11+D12+D13+U83+AA83+AA89+U89)*1 -> #DIV/0! | U15: =(D103-N7)/(D6+D9+D10+D11+D12+D13+U83+AA83+AA89+U89)*1 -> #DIV/0! | AC15: غير محسوب ذي الشهر | AE15: غير محسوب ذي الشهر | AG15: غير محسوب ذي الشهر | AL15: غير محسوب ذي الشهر | AN15: غير محسوب ذي الشهر | AP15: غير محسوب ذي الشهر | AU15: غير محسوب ذي الشهر | AW15: غير محسوب ذي الشهر | AY15: غير محسوب ذي الشهر | BD15: غير محسوب ذي الشهر | BF15: غير محسوب ذي الشهر | BH15: غير محسوب ذي الشهر | BM15: غير محسوب ذي الشهر | BO15: غير محسوب ذي الشهر | BQ15: غير محسوب ذي الشهر | BV15: غير محسوب ذي الشهر | BX15: غير محسوب ذي الشهر | BZ15: غير محسوب ذي الشهر | CE15: غير محسوب ذي الشهر | CG15: غير محسوب ذي الشهر | CI15: غير محسوب ذي الشهر | CN15: غير محسوب ذي الشهر | CP15: غير محسوب ذي الشهر | CR15: غير محسوب ذي الشهر | CW15: غير محسوب ذي الشهر | CY15: غير محسوب ذي الشهر | DA15: غير محسوب ذي الشهر | DF15: غير محسوب ذي الشهر | DH15: غير محسوب ذي الشهر | DJ15: غير محسوب ذي الشهر | DO15: غير محسوب ذي الشهر | DQ15: غير محسوب ذي الشهر | DS15: غير محسوب ذي الشهر
B16: شهر 1 | G16: بطاقة صراف الالي | H16: راتب الزوجة | I16: ILA | K16: تصليح الكورولا cv اكسل و لور ارم ٨٧ ديتار | N16: =DF30+DH30+DJ30+DF41+DH41+DJ41 -> 0 | O16: =CW30+CY30+DA30+CW41+CY41+DA41 -> 0 | P16: =DO30+DQ30+DS30+DO41+DQ41+DS41+DO8+DQ8+DS8+DO19+DQ19+DS19 -> 0 | Q16: =(D6+D9+D10+D11+D12+D13+U83+AA83+AA89+U89)*Q15/1 -> #DIV/0! | S16: =DF30+DH30+DJ30+DF41+DH41+DJ41 -> 0 | U16: =(D6+D9+D10+D11+D12+D13+U83+AA83+AA89+U89)*Q15/1 -> #DIV/0!
B17: شهر 2 | G17: بطاقة صراف الالي | H17: مصروف العائلة | I17: - | N17: =(Q15+O15+N15+P15) -> #DIV/0! | P17: مجموع النسبة المئوية الكلي | S17: =(U15+S15) -> #DIV/0! | U17: مجموع النسبة المئوية الكلي
B18: شهر 3 | G18: بطاقة صراف الالي | H18: أجار الشقة او المنزل | I18: - | N18: =N16+O16+Q16+P16 -> #DIV/0! | S18: =S16+U16 -> #DIV/0! | AC18: علاج 2 | AE18: علاج 4 | AG18: علاج 6 | AI18: علاج 7 | AL18: اجار الشقة ١٫٢ | AN18: اجار الشقة ١٫٤ | AP18: اجار الشقة ١٫٦ | AR18: اجار الشقة ١٫٧ | AU18: ماجلة البيت ١٫٢ | AW18: ماجلة البيت ١٫٤ | AY18: ماجلة البيت ١٫٦ | BA18: ماجلة البيت ١٫٧ | BD18: جميع الابيال ١٫٢ | BF18: جميع الابيال ١٫٤ | BH18: جميع الابيال ١٫٦ | BJ18: جميع الابيال ١٫٧ | BM18: بيل الكهرباء ١٫٢ | BO18: بيل الكهرباء ١٫٤ | BQ18: بيل الكهرباء ١٫٦ | BS18: بيل الكهرباء ١٫٧ | BV18: بترول الجميع ١٫٢ | BX18: بترول الجميع ١٫٤ | BZ18: بترول الجميع ١٫٦ | CB18: بترول الجميع ١٫٧ | CE18: قسط بطاقة الفيزا البنكية 1.2 | CG18: قسط بطاقة الفيزا البنكية 1.4 | CI18: قسط بطاقة الفيزا البنكية 1.6 | CK18: قسط بطاقة الفيزا البنكية 1.7 | CN18: راتب الزوجة 1.2 | CP18: راتب الزوجة 1.4 | CR18: راتب الزوجة 1.6 | CT18: راتب الزوجة 1.7 | CW18: عامل التنظيف لجميع السيارات 1.2 | CY18: عامل التنظيف لجميع السيارات 1.4 | DA18: عامل التنظيف لجميع السيارات 1.6 | DC18: عامل التنظيف لجميع السيارات 1.7 | DF18: جمعية 1.2 | DH18: جمعية 1.4 | DJ18: جمعية 1.6 | DL18: جمعية 1.7 | DO18: ادخار ( تأمين و تسجيل + ثياب العيد + الروضة ) 1.2 | DQ18: ادخار ( تأمين و تسجيل + ثياب العيد + الروضة ) 1.4 | DS18: ادخار ( تأمين و تسجيل + ثياب العيد + الروضة ) 1.6 | DU18: ادخار ( تأمين و تسجيل + ثياب العيد + الروضة ) 1.7
B19: شهر 4 | G19: بطاقة صراف الالي | H19: ماچلة البيت | I19: - | N19: =1-N17 -> #DIV/0! | P19: المتبقي من الراتب | S19: =1-S17 -> #DIV/0! | U19: المتبقي من الراتب | AC19: =VLOOKUP(G23,AC20:AD26,2,FALSE) -> 0 | AE19: =VLOOKUP(G23,AE20:AF26,2,FALSE) -> 0 | AG19: =VLOOKUP(G23,AG20:AH26,2,FALSE) -> 0 | AI19: =VLOOKUP(G23,AI20:AJ26,2,FALSE) -> 0 | AL19: =VLOOKUP(G18,AL20:AM26,2,FALSE) -> 0 | AN19: =VLOOKUP(G18,AN20:AO26,2,FALSE) -> 0 | AP19: =VLOOKUP(G18,AP20:AQ26,2,FALSE) -> 0 | AR19: =VLOOKUP(G18,AR20:AS26,2,FALSE) -> 0 | AU19: =VLOOKUP(G19,AU20:AV26,2,FALSE) -> 0 | AW19: =VLOOKUP(G19,AW20:AX26,2,FALSE) -> 0 | AY19: =VLOOKUP(G19,AY20:AZ26,2,FALSE) -> 0 | BA19: =VLOOKUP(G19,BA20:BB26,2,FALSE) -> 0 | BD19: =VLOOKUP(G20,BD20:BE26,2,FALSE) -> 0 | BF19: =VLOOKUP(G20,BF20:BG26,2,FALSE) -> 0 | BH19: =VLOOKUP(G20,BH20:BI26,2,FALSE) -> 0 | BJ19: =VLOOKUP(G20,BJ20:BK26,2,FALSE) -> 0 | BM19: =VLOOKUP(G21,BM20:BN26,2,FALSE) -> 0 | BO19: =VLOOKUP(G21,BO20:BP26,2,FALSE) -> 0 | BQ19: =VLOOKUP(G21,BQ20:BR26,2,FALSE) -> 0 | BS19: =VLOOKUP(G21,BS20:BT26,2,FALSE) -> 0 | BV19: =VLOOKUP(G27,BV20:BW26,2,FALSE) -> 0 | BX19: =VLOOKUP(G27,BX20:BY26,2,FALSE) -> 0 | BZ19: =VLOOKUP(G27,BZ20:CA26,2,FALSE) -> 0 | CB19: =VLOOKUP(G27,CB20:CC26,2,FALSE) -> 0 | CE19: =VLOOKUP(H68,CE20:CF26,2,FALSE) -> 0 | CG19: =VLOOKUP(H68,CG20:CH26,2,FALSE) -> 0 | CI19: =VLOOKUP(H68,CI20:CJ26,2,FALSE) -> 0 | CK19: =VLOOKUP(H68,CK20:CL26,2,FALSE) -> 0 | CN19: =VLOOKUP(G16,CN20:CO26,2,FALSE) -> 0 | CP19: =VLOOKUP(G16,CP20:CQ26,2,FALSE) -> 0 | CR19: =VLOOKUP(G16,CR20:CS26,2,FALSE) -> 0 | CT19: =VLOOKUP(G16,CT20:CU26,2,FALSE) -> 0 | CW19: =VLOOKUP(G28,CW20:CX26,2,FALSE) -> 0 | CY19: =VLOOKUP(G28,CY20:CZ26,2,FALSE) -> 0 | DA19: =VLOOKUP(G28,DA20:DB26,2,FALSE) -> 0 | DC19: =VLOOKUP(G28,DC20:DD26,2,FALSE) -> 0 | DF19: =VLOOKUP(G44,DF20:DG26,2,FALSE) -> 0 | DH19: =VLOOKUP(G44,DH20:DI26,2,FALSE) -> 0 | DJ19: =VLOOKUP(G44,DJ20:DK26,2,FALSE) -> 0 | DL19: =VLOOKUP(G44,DL20:DM26,2,FALSE) -> 0 | DO19: =VLOOKUP(G47,DO20:DP26,2,FALSE) -> 0 | DQ19: =VLOOKUP(G47,DQ20:DR26,2,FALSE) -> 0 | DS19: =VLOOKUP(G47,DS20:DT26,2,FALSE) -> 0 | DU19: =VLOOKUP(G47,DU20:DV26,2,FALSE) -> 0
B20: شهر 5 | G20: بطاقة صراف الالي | H20: جميع الابيال الانترنت و خطوط الهاتف | I20: - | N20: =(D6+D9+D10+D11+D12+D13+U83+AA83+AA89+U89)*N19/1 -> #DIV/0! | S20: =(D6+D9+D10+D11+D12+D13+U83+AA83+AA89+U89)*S19/1 -> #DIV/0! | AC20: NBK | AE20: NBK | AG20: NBK | AI20: NBK | AL20: NBK | AN20: NBK | AP20: NBK | AR20: NBK | AU20: NBK | AW20: NBK | AY20: NBK | BA20: NBK | BD20: NBK | BF20: NBK | BH20: NBK | BJ20: NBK | BM20: NBK | BO20: NBK | BQ20: NBK | BS20: NBK | BV20: NBK | BX20: NBK | BZ20: NBK | CB20: NBK | CE20: NBK | CG20: NBK | CI20: NBK | CK20: NBK | CN20: NBK | CP20: NBK | CR20: NBK | CT20: NBK | CW20: NBK | CY20: NBK | DA20: NBK | DC20: NBK | DF20: NBK | DH20: NBK | DJ20: NBK | DL20: NBK | DO20: NBK | DQ20: NBK | DS20: NBK | DU20: NBK
B21: شهر 6 | G21: بطاقة صراف الالي | H21: بيل الكهرباء و الماء | I21: - | AC21: ILA | AD21: =D23 -> 0 | AE21: ILA | AG21: ILA | AI21: ILA | AL21: ILA | AM21: =D18 -> 0 | AN21: ILA | AP21: ILA | AR21: ILA | AU21: ILA | AV21: =D19 -> 0 | AW21: ILA | AY21: ILA | BA21: ILA | BD21: ILA | BE21: =D20 -> 0 | BF21: ILA | BH21: ILA | BJ21: ILA | BM21: ILA | BN21: =D21 -> 0 | BO21: ILA | BQ21: ILA | BS21: ILA | BV21: ILA | BW21: =D27 -> 0 | BX21: ILA | BZ21: ILA | CB21: ILA | CE21: ILA | CF21: =D67 -> 0 | CG21: ILA | CI21: ILA | CK21: ILA | CN21: ILA | CO21: =D16 -> 0 | CP21: ILA | CR21: ILA | CT21: ILA | CW21: ILA | CX21: =D28 -> 0 | CY21: ILA | DA21: ILA | DC21: ILA | DF21: ILA | DG21: =D44 -> 0 | DH21: ILA | DJ21: ILA | DL21: ILA | DO21: ILA | DP21: =D47 -> 0 | DQ21: ILA | DS21: ILA | DU21: ILA
